Workbook

Sheet Equipos
A1: EQUIPOS (EDITABLE)
A3: Codigo | B3: Tipo Equipo | C3: Marca | D3: Modelo | E3: Año | F3: Ubicacion | G3: Responsable | H3: Estado Base | I3: Control Base | J3: Frecuencia Base | K3: Promedio Diario
A4: CD-100 | B4: Camión Slurry | C4: Volkswagen | D4: 26220 | E4: 2008 | F4: San Carlos | G4: Carlos Aedo | H4: Operativo | I4: HORAS | J4: 250 | K4: 0
A5: CD-102 | B5: Camión Tolva | C5: Man | D5: TGS 50480 | E5: 2018 | F5: San Nicolas | G5: Nelson Cancino | H5: Operativo | I5: HORAS | J5: 500 | K5: 6.54
A6: CD-103 | B6: Camión Tolva | C6: Man | D6: TGS 50480 | E6: 2018 | F6: TALLER | G6: Felipe Figueroa | H6: Fuera de Servicio | I6: HORAS | J6: 500
A7: CD-104 | B7: Camión Tolva | C7: Man | D7: TGS 50480 | E7: 2019 | F7: Emergencias Curico | G7: Nelson Cancino Papá | H7: Operativo | I7: HORAS | J7: 250 | K7: 215.17
A8: CD-105 | B8: Camión Tolva | C8: Man | D8: TGS 50480 | E8: 2018 | F8: Palmucho | G8: Eugenio Hormazabal | H8: Operativo | I8: HORAS | J8: 500 | K8: 97.16
A9: CD-106 | B9: Camión Tolva | C9: Man | D9: TGS 50480 | E9: 2019 | F9: Emergencias Curico | G9: Felipe Figueroa | H9: Operativo | I9: HORAS | J9: 500 | K9: 120.58
A10: CD-107 | B10: Camión Tolva | C10: Man | D10: TGS 50480 | E10: 2019 | F10: Taller | G10: Cesar Vergara | H10: Operativo | I10: HORAS | J10: 500 | K10: 147.06
A11: CD-108 | B11: Camión Slurry | C11: International | D11: 7600 | E11: 2008 | F11: Palmucho | G11: Patricio Salas | H11: Operativo | I11: HORAS | J11: 250 | K11: 0
A12: CD-109 | B12: Camión Plano | C12: Hino | D12: XZU 6.5 DCAB | E12: 2012 | F12: Palmucho | G12: Washington Sanzana | H12: Operativo | I12: KM | J12: 10000 | K12: 102.86
A13: CD-110 | B13: Camión Plano | C13: Jac | D13: Urban HFC1050K | E13: 2015 | F13: Cobquecura | G13: Rodolfo Vera | H13: Operativo | I13: HORAS | J13: 250 | K13: 70.85
A14: CD-111 | B14: Camión Plano | C14: Mercedes Benz | D14: Atego 1315 48 | E14: 2007 | F14: TALLER | G14: Sin asignar | H14: Fuera de Servicio | I14: HORAS | J14: 250
A15: CD-112 | B15: Camión Pintura | C15: No hay info | D15: No hay info | E15: No hay info | F15: TALLER | G15: Sin asignar | H15: Fuera de Servicio | I15: HORAS | J15: 250
A16: CD-113 | B16: Camión Imprimador | C16: Volkswagen | D16: 17180M | E16: 2011 | F16: Quirihue | G16: Frank Yegres | H16: Operativo | I16: HORAS | J16: 250 | K16: 0
A17: CD-114 | B17: Camión Imprimador | C17: Freightliner | D17: M2 112 | E17: 1998 | F17: Palmucho | G17: Juan Espinoza | H17: Operativo | I17: HORAS | J17: 250 | K17: 2.71
A18: CD-115 | B18: Tracto Camión | C18: Mercedes Benz | D18: LS 1634 45 | E18: 2011 | F18: Taller ext | G18: Manuel Pacheco | H18: Taller | I18: KM | J18: 10000 | K18: 391.03
A19: CD-116 | B19: Camión Plano | C19: Wolkswagen | D19: 9150E | E19: 2012 | F19: Taller | G19: Nicolas Morales | H19: Operativo | I19: HORAS | J19: 250 | K19: 0
A20: CD-117 | B20: Camión Slurry | C20: No hay info | D20: No hay info | E20: No hay info | F20: Taller | G20: Sin asignar | H20: Fuera de Servicio | I20: HORAS | J20: 250 | K20: 0
A21: CD-118 | B21: Camión Plano | C21: Freightliner | D21: M2 106 | E21: 2010 | F21: Taller | G21: Carlos Vasquez | H21: Operativo | I21: HORAS | J21: 250 | K21: 292.62
A22: CD-119 | B22: Camión Combustible | C22: Hino | D22: GH8JMTA | E22: 2013 | F22: San Nicolas | G22: Nector Muñoz | H22: Operativo | I22: HORAS | J22: 250 | K22: 5.15
A23: CD-120 | B23: Camión Tolva | C23: Man | D23: TGS 40400 BB | E23: 2024 | F23: Cobquecura | G23: Pablo Torres | H23: Operativo | I23: HORAS | J23: 500 | K23: 121.61
A24: CD-121 | B24: Camión Tolva | C24: Man | D24: TGS 40400 BB | E24: 2024 | F24: Cobquecura | G24: Chandor Ruiz | H24: Operativo | I24: HORAS | J24: 500 | K24: 105.37
A25: CD-122 | B25: Camión Tolva | C25: Man | D25: TGS 40400 BB | E25: 2024 | F25: San Nicolas | G25: Renan Aguilera | H25: Operativo | I25: HORAS | J25: 500 | K25: 1.36
A26: CD-123 | B26: Camión Tolva | C26: Man | D26: TGS 40400 BB | E26: 2024 | F26: San Nicolas | G26: Wilson Salazar | H26: Operativo | I26: HORAS | J26: 500 | K26: 42.24
A27: CD-124 | B27: Camión Tolva | C27: Man | D27: TGS 40400 BB | E27: 2024 | H27: Fuera de Servicio | I27: HORAS | J27: 500 | K27: 0
A28: CD-125 | B28: Camión Maxus | C28: Maxus | D28: C35 2.0 | E28: 2023 | F28: Taller | G28: Patricio Mora | H28: Operativo | I28: HORAS | J28: 250 | K28: 259.61
A29: CD-126 | B29: Camión Maxus | C29: Maxus | D29: C35 2.0 | E29: 2023 | F29: Taller (Kauffman) | G29: Manuel Piñaleo | H29: Operativo | I29: HORAS | J29: 250
A30: CD-127 | B30: Camión Pluma | C30: International | D30: 4300 | E30: 2012 | F30: Taller | G30: Osvaldo Faundez | H30: Operativo | I30: HORAS | J30: 250 | K30: 127.61
A31: CD-128 | B31: Camión slurry | C31: Mack | D31: GU 813 | E31: 2012 | F31: Palmucho | G31: Marcelo Candelara | H31: Operativo | I31: HORAS | J31: 250 | K31: 24.84
A32: CD-129 | B32: Camión Aljibe | C32: Mack | D32: GU 813 | E32: 2012 | F32: TALLER | G32: Sin asignar | H32: Fuera de Servicio | I32: HORAS | J32: 250
A33: CD-130 | B33: Camión Tolva | C33: Renault | D33: K480 | E33: 2021 | F33: Taller | G33: Sin asignar | H33: Fuera de Servicio | I33: HORAS | J33: 500 | K33: 58.71
A34: CD-131 | B34: Camión Tolva | C34: Renault | D34: K480 | E34: 2021 | F34: Taller | G34: Sin asignar | H34: Fuera de Servicio | I34: HORAS | J34: 250 | K34: 275
A35: CD-132 | B35: Camión Tolva | C35: Renault | D35: K480 | E35: 2021 | F35: Palmucho | G35: Cesar Vergara | H35: Operativo | I35: HORAS | J35: 500 | K35: 168.21
A36: CD-133 | B36: Camión Plano | C36: International | D36: 7400 | E36: 2010 | F36: TALLER | G36: Sin asignar | H36: Fuera de Servicio | I36: HORAS | J36: 250
A37: CD-134 | B37: Camión Plano | C37: International | D37: 4300 | E37: 2012 | F37: TALLER | G37: Sin asignar | H37: Taller | I37: HORAS | J37: 250 | K37: 0
A38: CD-135 | B38: Camión Plano | C38: Mack | D38: GU 813 | E38: 2014 | F38: TALLER | G38: Sin asignar | H38: Fuera de Servicio | I38: HORAS | J38: 250
A39: CD-136 | B39: Camión Combustible | C39: Hino | D39: HZU | E39: 2015 | F39: Obras Varias | G39: Orlando Sanchez | H39: Operativo | I39: KM | J39: 10000 | K39: 81.79
A40: CD-137 | B40: Tracto Camión | C40: Mercedes Benz | D40: Axor 1936 | E40: 2014 | F40: Taller | G40: Manuel Pacheco | H40: Operativo | I40: HORAS | J40: 250 | K40: 139.79
A41: CD-138 | B41: Camion Imprimador | C41: Sterling | D41: L7500 | F41: San Carlos | G41: Duban Rio | H41: Operativo | I41: HORAS | J41: 250 | K41: 354.05
...

Sheet Lecturas
A1: LECTURAS (EDITABLE)
A3: Fecha | B3: Codigo | C3: Horometro | D3: Kilometraje | E3: Obra / Ubicacion | F3: Responsable | G3: Observacion
A4: 46065 | B4: CD-100 | C4: 2852
A5: 44607 | B5: CD-100 | C5: 1937
A6: 44553 | B6: CD-100 | C6: 1683
A7: 44329 | B7: CD-100 | C7: 985
A8: 46132 | B8: CD-102 | C8: 10496 | E8: SAN NICOLAS
A9: 46115 | B9: CD-102 | C9: 10378 | D9: 260271 | E9: Quirihue
A10: 46101 | B10: CD-102 | C10: 10368 | D10: 262575 | E10: Quirihue
A11: 46099 | B11: CD-102 | C11: 10361 | D11: 262326 | E11: Quirihue
A12: 45056 | B12: CD-103 | C12: 5327 | D12: 126893
A13: 46114 | B13: CD-104 | D13: 261250 | E13: Curicó
A14: 46113 | B14: CD-104 | D14: 260933 | E14: Curicó
A15: 46108 | B15: CD-104 | E15: Curicó | F15: Nelson Omar Cancino Arellano | G15: Carga combustible importada 2026-04-01
A16: 46083 | B16: CD-104 | C16: 8820 | D16: 258456
A17: 46107 | B17: CD-105 | C17: 10623 | D17: 257067 | E17: Palmucho
A18: 46107 | B18: CD-105 | C18: 10611 | D18: 256570 | E18: Palmucho
A19: 46105 | B19: CD-105 | C19: 10599 | D19: 256409 | E19: Palmucho
A20: 46105 | B20: CD-105 | C20: 10590 | D20: 256246 | E20: Palmucho
A21: 46105 | B21: CD-106 | C21: 8345 | E21: Taller
A22: 46070 | B22: CD-106 | D22: 250115
A23: 46052 | B23: CD-106 | C23: 8328 | D23: 168556
A24: 46049 | B24: CD-106 | C24: 8221 | D24: 168332
A25: 46092 | B25: CD-107 | C25: 10923 | E25: San Nicolas
A26: 46087 | B26: CD-107 | C26: 10837
A27: 46086 | B27: CD-107 | C27: 10820
A28: 46065 | B28: CD-107 | C28: 10863
A29: 46107 | B29: CD-108 | D29: 48763 | E29: Palmucho
A30: 46077 | B30: CD-108 | D30: 98639
A31: 46077 | B31: CD-108 | D31: 98639
A32: 46062 | B32: CD-108 | D32: 98550
A33: 46106 | B33: CD-109 | D33: 190409 | E33: Palmucho
A34: 46101 | B34: CD-109 | D34: 190215 | E34: Palmucho
A35: 46098 | B35: CD-109 | D35: 190022 | E35: Palmucho
A36: 46080 | B36: CD-109 | D36: 189344
A37: 46111 | B37: CD-110 | D37: 275886 | E37: Cobquecura
A38: 46101 | B38: CD-110 | D38: 275095 | E38: Cobquecura
A39: 46098 | B39: CD-110 | D39: 274769 | E39: Cobquecura
A40: 46078 | B40: CD-110 | D40: 274320
A41: 46050 | B41: CD-113 | D41: 121065
...

Sheet Mantenciones
A3: Fecha | B3: Codigo | C3: Tipo Mantencion | D3: Lectura | E3: EsPM | F3: Folio | G3: Lugar | H3: Mecanico | I3: Costo Mantencion CLP | J3: Estado
A4: 45967 | B4: MD-57 | C4: Mantencion PM2 | D4: 13469 | E4: Sí | F4: 15910 | J4: Finalizada
A5: 45954 | B5: MD-83 | C5: Mantencion PM2 | D5: 7636 | E5: Sí | F5: 15906 | J5: Finalizada
A6: 45967 | B6: MD-68 | C6: Mantencion PM2 | D6: 3240 | E6: Sí | F6: 15908 | J6: Finalizada
A7: 46042 | B7: MD-83 | C7: Mantencion PM2 | D7: 8046 | E7: Sí | J7: Finalizada
A8: 45972 | B8: CD-88 | C8: Mantencion PM2 | D8: 1453 | E8: Sí | F8: 15913 | J8: Finalizada
A9: 45980 | B9: CD-102 | C9: Mantencion PM2 | D9: 9695 | E9: Sí | F9: 15914 | J9: Finalizada
A10: 45982 | B10: MD-95 | C10: Mantencion PM2 | D10: 1413 | E10: Sí | F10: 15178 | J10: Finalizada
A11: 45985 | B11: MD-88 | C11: Mantencion PM2 | D11: 6327 | E11: Sí | F11: 15179 | J11: Finalizada
A12: 45993 | B12: MD-102 | C12: Mantencion PM2 | D12: 5321 | E12: Sí | F12: 15184 | J12: Finalizada
A13: 45995 | B13: MD-94 | C13: Mantencion PM2 | D13: 2060 | E13: Sí | F13: 15186 | J13: Finalizada
A14: 46008 | B14: VD-78 | C14: Mantencion PM1 | D14: 128090 | E14: Sí | F14: SN | J14: Finalizada
A15: 46009 | B15: VD-77 | C15: Mantencion PM1 | D15: 128838 | E15: Sí | F15: SN | J15: Finalizada
A16: 46014 | B16: CD-97 | C16: Mantencion PM1 | D16: 530211 | E16: Sí | F16: SN | J16: Finalizada
A17: 46015 | B17: CD-69 | C17: Mantencion PM2 | D17: 461588 | E17: Sí | F17: 389 | J17: Finalizada
A18: 46028 | B18: MD-73 | C18: Mantencion PM1 | D18: 17076 | E18: Sí | F18: 389 | J18: Finalizada
A19: 46028 | B19: CD-142 | C19: Mantencion PM1 | D19: 331891 | E19: Sí | F19: 389 | J19: Finalizada
A20: 45971 | B20: MD-96 | C20: Mantencion PM1 | D20: 1496 | E20: Sí | F20: 15912 | J20: Finalizada
A21: 46031 | B21: MD-109 | C21: Mantencion PM1 | D21: 87661 | E21: Sí | F21: 389 | J21: Finalizada
A22: 46034 | B22: VD-119 | C22: Mantencion PM1 | E22: Sí | F22: 389 | J22: Finalizada
A23: 46034 | B23: VD-84 | C23: Mantencion PM1 | D23: 118530 | E23: Sí | F23: SN | J23: Finalizada
A24: 46034 | B24: ED-73 | C24: Mantencion PM1 | D24: 681 | E24: Sí | J24: Finalizada
A25: 45908 | B25: MD-107 | C25: Mantencion PM2 | D25: 393 | E25: Sí | F25: 15911 | J25: Finalizada
A26: 46035 | B26: VD-91 | C26: Mantencion PM1 | D26: 105667 | E26: Sí | F26: 389 | J26: Finalizada
A27: 46036 | B27: VD-76 | C27: Mantencion PM1 | D27: 157018 | E27: Sí | F27: 389 | J27: Finalizada
A28: 45967 | B28: MD-107 | C28: Mantencion PM2 | D28: 748 | E28: Sí | F28: 15911 | J28: Finalizada
A29: 46037 | B29: VD-95 | C29: Mantencion PM1 | D29: 136208 | E29: Sí | F29: 389 | J29: Finalizada
A30: 45967 | B30: MD-100 | C30: Mantencion PM2 | D30: 2000 | E30: Sí | F30: 15909 | J30: Finalizada
A31: 46028 | B31: MD-100 | C31: Mantencion PM2 | D31: 2600 | E31: Sí | F31: 15920 | J31: Finalizada
A32: 46035 | B32: MD-107 | C32: Mantencion PM2 | D32: 1112 | E32: Sí | F32: 15921 | J32: Finalizada
A33: 46044 | B33: CD-132 | C33: Mantencion PM1 | D33: 189042 | E33: Sí | J33: Finalizada
A34: 46044 | B34: CD-106 | C34: Mantencion PM1 | D34: 8319 | E34: Sí | J34: Finalizada
A35: 46049 | B35: MD-75 | C35: Mantencion PM2 | E35: Sí | F35: 15440 | J35: Finalizada
A36: 46050 | B36: MD-101 | C36: Mantencion PM1 | D36: 9814 | E36: Sí | J36: Finalizada
A37: 46050 | B37: VD-111 | C37: Mantencion PM1 | D37: 54500 | E37: Sí | J37: Finalizada
A38: 46057 | B38: MD-56 | C38: Mantencion PM1 | D38: 15554 | E38: Sí | J38: Finalizada
A39: 46065 | B39: VD-78 | C39: Mantencion PM1 | D39: 138841 | E39: Sí | J39: Finalizada
A40: 46066 | B40: CD-87 | C40: Mantencion PM1 | D40: 9302 | E40: Sí | J40: Finalizada
A41: 46072 | B41: VD-122 | C41: Mantencion PM1 | D41: 39996 | E41: Sí | F41: 16152 | J41: Finalizada
A42: 46073 | B42: VD-125 | C42: Mantencion PM1 | D42: 58306 | E42: Sí | F42: Ext | J42: Finalizada
...

Sheet Repuestos
A1: Repuestos Bodega Demotron
A3: Codigo OEM | B3: Nombre | C3: Categoria | D3: Stock | E3: Precio | F3: Ubicacion
A4: KIT-MAX-T60 2.0 | B4: Kit Filtro Maxus 2.0 | C4: KIT COMPLETO FILTROS | D4: 2 | E4: 23799.9
A5: KIT-MAX-T60 2.8 | B5: Kit Filtro Maxus 2.8 | C5: KIT COMPLETO FILTROS | D5: 7 | E5: 24499
A6: KIT-PEU-PART | B6: Kit Filtros Peugeot Patner | C6: KIT COMPLETO FILTROS | D6: 1 | E6: 24600
A7: KIT-ZXAUTO-T | B7: Kit Filtro Zx Terralord | C7: KIT COMPLETO FILTROS | D7: 2 | E7: 35301.29
A8: KIT-HINO-300 | B8: Kit Filtro HINO 300 | C8: KIT COMPLETO FILTROS | D8: 3 | E8: 143221.43
A9: KIT-HINO-500 | B9: Kit Filtros CD-109 | C9: KIT COMPLETO FILTROS | D9: 0 | E9: 147685.2
A10: KIT-MAH-2.2 | B10: Kit Filtro Maxindra | C10: KIT COMPLETO FILTROS | D10: 1 | E10: 23899.89
A11: KIT-SSanyong | B11: Kit Filtros Ssangyong | C11: KIT COMPLETO FILTROS | D11: 2 | E11: 30899.98
A12: KIT-MAN-TT | B12: Kit Filtros Man Tolva | C12: KIT COMPLETO FILTROS | D12: 2 | E12: 190541
A13: KIT-DOO-225la | B13: Kit Filtros Doosan DX225la | C13: KIT COMPLETO FILTROS | D13: 4 | E13: 200572
A14: KIT-DOO-300la | B14: Kit Filtros Doosan DX300la | C14: KIT COMPLETO FILTROS | D14: 1 | E14: 312122
A15: KIT-STERL-7500 | B15: Kit Filtros Sterling 7500 | C15: KIT COMPLETO FILTROS | D15: 1 | E15: 229300
... A20: KIT-INTER-4300 | B20: KIt Filtros International 4300 | C20: KIT COMPLETO FILTROS | D20: 1 | E20: 136602
A21: KIT-FREI-112 | B21: KIt Filtros Freightliner M2 112 | C21: KIT COMPLETO FILTROS | D21: 1
A22: KIT-FREI-106 | B22: KIt Filtros Freightliner M2 106 | C22: KIT COMPLETO FILTROS | D22: 1
A23: KIT-MACK-GU | B23: Kit Filtros Mack GU 813 | C23: KIT COMPLETO FILTROS | D23: 1
A24: KIT-Bomag-D40 | B24: Kit Filtros Bomag BW211 D40 | C24: KIT COMPLETO FILTROS | D24: 1
A25: KIT-554K-JD | B25: Kit Filtros John Deree 554K | C25: KIT COMPLETO FILTROS | D25: 1
A26: KIT-MB-1634 | B26: Kit Filtros Mercedes Benz LS1634 | C26: KIT COMPLETO FILTROS | D26: 1
A27: KIT-CASE-580M | B27: Kit Filtros CASE 580M | C27: KIT COMPLETO FILTROS | D27: 2
A28: KIT-KEN-T800 | B28: Kit Filtros Kenworth T801 | C28: KIT COMPLETO FILTROS | D28: 1
A29: KIT-HAMM | B29: Kit Filtros Hamm GRW16 | C29: KIT COMPLETO FILTROS | D29: 3
A30: KIT-VOLK-26 | B30: Kit Filtros Volkswagen 26220 | C30: KIT COMPLETO FILTROS | D30: 1
A31: KIT-SANY-BHL | B31: Kit Filtros Sany BHL75A | C31: KIT COMPLETO FILTROS | D31: 1 | E31: 227618
A32: KIT-CAT-416 | B32: Kit Filtros CAT 416 E | C32: KIT COMPLETO FILTROS | D32: 1 | E32: 213063
A33: LF3345 | B33: LF3345 | C33: FILTRO DE ACEITE | D33: 1
A34: PA3761 | B34: PA3761 | C34: FILTRO DE AIRE MOTOR | D34: 1
A35: LF3827 | B35: LF3827 | C35: FILTRO DE ACEITE | D35: 1
A36: FF5380 | B36: FF5380 | C36: FILTRO DE COMBUSTIBLE | D36: 1
A37: FS19914 | B37: FS19914 | C37: FILTRO DECANTADOR | D37: 1
A38: FS1212 | B38: FS1212 | C38: FILTRO DECANTADOR | D38: 1
A39: PSC75 | B39: PSC75 | C39: FILTRO DE COMBUSTIBLE | D39: 1
A40: KIT-724K-JD | B40: Kit Filtros John Deree 724K | C40: KIT COMPLETO FILTROS | D40: 1 | E40: 800603
A41: KIT-CAT-390 | B41: Kit Filtros CAT 390 | C41: KIT COMPLETO FILTROS | D41: 1 | E41: 212500
A42: KIT-REN-K480 | B42: Kit Filtros Renault K480 | C42: KIT COMPLETO FILTROS | D42: 2 | E42: 380600
A43: KIT-MAXUS-C35 | B43: Kit Filtros Maxus C35 | C43: KIT COMPLETO FILTROS | D43: 1
A44: KIT-Bomag-212 | B44: Kit Filtros Bomag BW212 D40 | C44: KIT COMPLETO FILTROS | D44: 1
A45: KIT-HYN-HL7709S | B45: Kit Filtros Hyundai HL7709S | C45: KIT COMPLETO FILTROS | D45: 2

Sheet Recetas_Kits
A1: KIT de Repuestos
A3: Modelo Equipo | B3: SKU Repuesto | C3: Cantidad
A4: 12M | C4: 1
A5: 160H | C5: 1
A6: 17180M | C6: 1
A7: 210 LC | C7: 1
A8: 210 Lc | C8: 1
A9: 26220 | B9: KIT-VOLK-26 | C9: 1
A10: 330D | C10: 1
A11: 350GLC | C11: 1
A12: 3CX 4X4 | C12: 1
A13: 416 E | B13: KIT-CAT-416 | C13: 1
A14: 4300 | B14: KIT-INTER-4300 | C14: 1
A15: 467 Zx | C15: 1
A16: 4x2 6MT | C16: 1
A17: 512 | C17: 1
A18: 554K | B18: KIT-554K-JD | C18: 1
A19: 580M | B19: KIT-CASE-580M | C19: 1
A20: 624K | C20: 1
A21: 670G | C21: 1
A22: 674 | C22: 1
A23: 724K | C23: 1
A24: 7400 | C24: 1
A25: 7600 | C25: 1
A26: 770G | C26: 1
A27: 772 D | B27: KIT-772D-JD | C27: 1
A28: 772G | C28: 1
A29: 915 C 37 | C29: 1
A30: 9150 EOD | C30: 1
A31: 9150E | C31: 1
A32: 966H | B32: KIT-CAT-966H | C32: 1
A33: Atego 1015 | C33: 1
A34: Atego 1315 48 | C34: 1
A35: Axor 1936 | C35: 1
A36: B90B 4X4 | C36: 1
A37: BERLINGO B9 C HDI 1.6 | C37: 1
A38: BHL75A | B38: KIT-SANY-BHL | C38: 1
A39: BW211 D40 | B39: KIT-Bomag-D40 | C39: 1
A40: BW211 D5 | C40: 1
A41: Berlingo C Electric | C41: 1
...

Sheet Compras PM
A1: COMPRAS PM (EDITABLE)
A3: Fecha | B3: OC | C3: Codigo | D3: Descripcion | E3: Proveedor | F3: Costo PM CLP | G3: Regla | H3: Estado OC
A4: 46065.519 | B4: DEMO-02-7633 | C4: VD-115 | D4: SC-2-6076 KIT FILTROS PEUGEOT | E4: SOCIEDAD COMERCIAL SOCOFIL LIMITADA | F4: 32201.4 | G4: Directo Equipo | H4: OC Aprobada
A5: 46065.519 | B5: DEMO-02-7633 | C5: VD-116 | D5: SC-2-6076 KIT FILTROS PEUGEOT | E5: SOCIEDAD COMERCIAL SOCOFIL LIMITADA | F5: 32201.4 | G5: Directo Equipo | H5: OC Aprobada
A6: 46065.519 | B6: DEMO-02-7633 | C6: VD-117 | D6: SC-2-6076 KIT FILTROS PEUGEOT | E6: SOCIEDAD COMERCIAL SOCOFIL LIMITADA | F6: 32201.4 | G6: Directo Equipo | H6: OC Aprobada
A7: 46065.519 | B7: DEMO-02-7633 | C7: VD-118 | D7: SC-2-6076 KIT FILTROS PEUGEOT | E7: SOCIEDAD COMERCIAL SOCOFIL LIMITADA | F7: 32201.4 | G7: Directo Equipo | H7: OC Aprobada
A8: 46065.519 | B8: DEMO-02-7633 | C8: VD-119 | D8: SC-2-6076 KIT FILTROS PEUGEOT | E8: SOCIEDAD COMERCIAL SOCOFIL LIMITADA | F8: 32201.4 | G8: Directo Equipo | H8: OC Aprobada
A9: 46065.519 | B9: DEMO-02-7633 | C9: VD-120 | D9: SC-2-6076 KIT FILTROS PEUGEOT | E9: SOCIEDAD COMERCIAL SOCOFIL LIMITADA | F9: 32201.4 | G9: Directo Equipo | H9: OC Aprobada
A10: 46065.519 | B10: DEMO-02-7633 | C10: VD-121 | D10: SC-2-6076 KIT FILTROS PEUGEOT | E10: SOCIEDAD COMERCIAL SOCOFIL LIMITADA | F10: 32201.4 | G10: Directo Equipo | H10: OC Aprobada
A11: 46065.519 | B11: DEMO-02-7633 | C11: VD-122 | D11: SC-2-6076 KIT FILTROS PEUGEOT | E11: SOCIEDAD COMERCIAL SOCOFIL LIMITADA | F11: 32201.4 | G11: Directo Equipo | H11: OC Aprobada
A12: 46065.519 | B12: DEMO-02-7633 | C12: VD-123 | D12: SC-2-6076 KIT FILTROS PEUGEOT | E12: SOCIEDAD COMERCIAL SOCOFIL LIMITADA | F12: 32201.4 | G12: Directo Equipo | H12: OC Aprobada
A13: 46065.519 | B13: DEMO-02-7633 | C13: VD-124 | D13: SC-2-6076 KIT FILTROS PEUGEOT | E13: SOCIEDAD COMERCIAL SOCOFIL LIMITADA | F13: 32201.4 | G13: Directo Equipo | H13: OC Aprobada
A14: 46069.447 | B14: DEMO-02-7643 | C14: CD-87 | D14: SC-02-6085 KIT DE FILTROS MANTENCIO | E14: SOCIEDAD COMERCIAL SOCOFIL LIMITADA | F14: 5764.6988 | G14: Prorrateo MAN | H14: OC Aprobada
A15: 46069.447 | B15: DEMO-02-7643 | C15: CD-88 | D15: SC-02-6085 KIT DE FILTROS MANTENCIO | E15: SOCIEDAD COMERCIAL SOCOFIL LIMITADA | F15: 5764.6988 | G15: Prorrateo MAN | H15: OC Aprobada
... A30: 46069.447 | B30: DEMO-02-7643 | C30: CD-89 | D30: SC-02-6085 KIT DE FILTROS MANTENCIO | E30: SOCIEDAD COMERCIAL SOCOFIL LIMITADA | F30: 5764.6988 | G30: Prorrateo MAN | H30: OC Aprobada
A31: 46069.64 | B31: DEMO-02-7652 | C31: =_xlfn.TEXTAFTER(TRIM(tblComprasPM[[#This Row],[Descripcion]]), " ", -1) -> CD-69 | D31: SC-02 KIT DE FILTROS SCANIA CD-69 | E31: COM. PUENTES DE MAULE LTDA. | F31: 162393.35 | G31: Directo Equipo | H31: OC Aprobada
A32: 46070.75 | B32: DEMO-02-7664 | C32: =_xlfn.TEXTAFTER(TRIM(tblComprasPM[[#This Row],[Descripcion]]), " ", -1) -> CD-45 | D32: SC-02-FILTROS CD-45 | E32: COM. PUENTES DE MAULE LTDA. | F32: 108651.76 | G32: Directo Equipo | H32: OC Aprobada
A33: 46071.353 | B33: DEMO-02-7663 | C33: =_xlfn.TEXTAFTER(TRIM(tblComprasPM[[#This Row],[Descripcion]]), " ", -1) -> CD-45 | D33: SC-02-FILTROS CD-45 | E33: SALINAS Y FABRES | F33: 59673.74 | G33: Directo Equipo | H33: OC Enviada a Proveedor
A34: 46071.627 | B34: DEMO-02-7668 | C34: =_xlfn.TEXTAFTER(TRIM(tblComprasPM[[#This Row],[Descripcion]]), " ", -1) -> CD-119 | D34: SC-02-6089 KIT DE FILTROS CD-119 | E34: AUTOMOTORA ALAMEDA SPA | F34: 201663.35 | G34: Directo Equipo | H34: OC Aprobada
A35: 46072.422 | B35: DEMO-02-7672 | C35: =_xlfn.TEXTAFTER(TRIM(tblComprasPM[[#This Row],[Descripcion]]), " ", -1) -> CD-88 | D35: SC-02-6090 FILTROS CD-88 | E35: AUTOMOTORA ALAMEDA SPA | F35: 402316.39 | G35: Directo Equipo | H35: OC Aprobada
A36: 46072.697 | B36: DEMO-02-7676 | C36: =_xlfn.TEXTAFTER(TRIM(tblComprasPM[[#This Row],[Descripcion]]), " ", -1) -> MD-84 | D36: SC-02-6093 KIT FILTROS MD-84 | E36: SALINAS Y FABRES | F36: 456581.58 | G36: Directo Equipo | H36: OC Enviada a Proveedor
A37: 46073.411 | B37: DEMO-02-7682 | C37: CD-102 | D37: SC-02-FILTROS CAMIONES MAN (STOCK T | E37: AUTOMOTORA ALAMEDA SPA | F37: 13095.53 | G37: Prorrateo MAN | H37: OC Aprobada
A38: 46073.411 | B38: DEMO-02-7682 | C38: CD-104 | D38: SC-02-FILTROS CAMIONES MAN (STOCK T | E38: AUTOMOTORA ALAMEDA SPA | F38: 13095.53 | G38: Prorrateo MAN | H38: OC Aprobada
A39: 46073.411 | B39: DEMO-02-7682 | C39: CD-105 | D39: SC-02-FILTROS CAMIONES MAN (STOCK T | E39: AUTOMOTORA ALAMEDA SPA | F39: 13095.53 | G39: Prorrateo MAN | H39: OC Aprobada
A40: 46073.411 | B40: DEMO-02-7682 | C40: CD-106 | D40: SC-02-FILTROS CAMIONES MAN (STOCK T | E40: AUTOMOTORA ALAMEDA SPA | F40: 13095.53 | G40: Prorrateo MAN | H40: OC Aprobada
A41: 46073.411 | B41: DEMO-02-7682 | C41: CD-107 | D41: SC-02-FILTROS CAMIONES MAN (STOCK T | E41: AUTOMOTORA ALAMEDA SPA | F41: 13095.53 | G41: Prorrateo MAN | H41: OC Aprobada
A42: 46073.411 | B42: DEMO-02-7682 | C42: CD-120 | D42: SC-02-FILTROS CAMIONES MAN (STOCK T | E42: AUTOMOTORA ALAMEDA SPA | F42: 13095.53 | G42: Prorrateo MAN | H42: OC Aprobada
A43: 46073.411 | B43: DEMO-02-7682 | C43: CD-121 | D43: SC-02-FILTROS CAMIONES MAN (STOCK T | E43: AUTOMOTORA ALAMEDA SPA | F43: 13095.53 | G43: Prorrateo MAN | H43: OC Aprobada
A44: 46073.411 | B44: DEMO-02-7682 | C44: CD-122 | D44: SC-02-FILTROS CAMIONES MAN (STOCK T | E44: AUTOMOTORA ALAMEDA SPA | F44: 13095.53 | G44: Prorrateo MAN | H44: OC Aprobada
A45: 46073.411 | B45: DEMO-02-7682 | C45: CD-123 | D45: SC-02-FILTROS CAMIONES MAN (STOCK T | E45: AUTOMOTORA ALAMEDA SPA | F45: 13095.53 | G45: Prorrateo MAN | H45: OC Aprobada
A46: 46073.411 | B46: DEMO-02-7682 | C46: CD-87 | D46: SC-02-FILTROS CAMIONES MAN (STOCK T | E46: AUTOMOTORA ALAMEDA SPA | F46: 13095.53 | G46: Prorrateo MAN | H46: OC Aprobada
A47: 46073.411 | B47: DEMO-02-7682 | C47: CD-88 | D47: SC-02-FILTROS CAMIONES MAN (STOCK T | E47: AUTOMOTORA ALAMEDA SPA | F47: 13095.53 | G47: Prorrateo MAN | H47: OC Aprobada
A48: 46073.411 | B48: DEMO-02-7682 | C48: CD-89 | D48: SC-02-FILTROS CAMIONES MAN (STOCK T | E48: AUTOMOTORA ALAMEDA SPA | F48: 13095.53 | G48: Prorrateo MAN | H48: OC Aprobada
... A53: 46073.411 | B53: DEMO-02-7682 | C53: CD-90 | D53: SC-02-FILTROS CAMIONES MAN (STOCK T | E53: AUTOMOTORA ALAMEDA SPA | F53: 13095.53 | G53: Prorrateo MAN | H53: OC Aprobada
A54: 46073.524 | B54: DEMO-02-7686 | C54: =_xlfn.TEXTAFTER(TRIM(tblComprasPM[[#This Row],[Descripcion]]), " ", -1) -> VD-29 | D54: SC-02-6095 KIR FILTROS VD-29 | E54: KAUFMANN S A VEHICULOS MOTORIZADOS | F54: 61356.4 | G54: Directo Equipo | H54: OC Aprobada
A55: 46073.541 | B55: DEMO-02-7688 | C55: CD-106 | D55: FILTROS BOTELLA MAN | E55: FORTI SPA | F55: 7700 | G55: Prorrateo MAN | H55: OC Aprobada
A56: 46073.541 | B56: DEMO-02-7688 | C56: CD-107 | D56: FILTROS BOTELLA MAN | E56: FORTI SPA | F56: 7700 | G56: Prorrateo MAN | H56: OC Aprobada
A57: 46073.541 | B57: DEMO-02-7688 | C57: CD-120 | D57: FILTROS BOTELLA MAN | E57: FORTI SPA | F57: 7700 | G57: Prorrateo MAN | H57: OC Aprobada
A58: 46073.541 | B58: DEMO-02-7688 | C58: CD-121 | D58: FILTROS BOTELLA MAN | E58: FORTI SPA | F58: 7700 | G58: Prorrateo MAN | H58: OC Aprobada
A59: 46073.541 | B59: DEMO-02-7688 | C59: CD-122 | D59: FILTROS BOTELLA MAN | E59: FORTI SPA | F59: 7700 | G59: Prorrateo MAN | H59: OC Aprobada
...

Sheet Bodega
A1: BODEGA (EDITABLE)
A3: Folio | B3: Fecha | C3: Equipo | D3: Envio | E3: Persona que retiro | F3: Destino | G3: Comentario | H3: Codigo
B4: 46057 | C4: MD-56 | D4: Filtros Completos | F4: Taller | H4: MD-56
B5: 46058 | C5: MD-110 | D5: Filtros Completos | F5: Taller | H5: MD-110
B6: 46060 | C6: CD-104 | D6: Filtros Completos | F6: Taller | H6: CD-104
A7: 18005 | B7: 46062 | C7: CD-115 | D7: Filtros Incompletos | E7: JC Celedon | F7: Taller | G7: Filtro Secador de Aire | H7: CD-115
A8: 18053 | B8: 46065 | C8: MD-68 | D8: Filtros Completos | E8: Osvaldo Faundez | F8: San Nicolas | H8: MD-68
A9: 18039 | B9: 46071 | C9: VD-112 | D9: Filtro Completros | E9: Luis Valenzuela | F9: Taller | H9: VD-112
A10: 18043 | B10: 46072 | C10: VD-120 | D10: Filtro Completros | E10: Daniel Andrade | F10: Taller | H10: VD-120
A11: 18093 | B11: 46072 | C11: VD-120 | D11: Filtros Completos | E11: Marcos Soto | F11: Taller | H11: VD-120
A12: 18093 | B12: 46072 | C12: VD-122 | D12: Filtros Completos | E12: Marcos Soto | F12: Taller | H12: VD-122
A13: 18206 | B13: 46073 | C13: VD-60 | D13: Filtro Completros | E13: Carlos Verdugo | F13: Q-61 | H13: VD-60
A14: 18207 | B14: 46073 | C14: MD-41 | D14: Filtro Completros | E14: Carlos Verdugo | F14: Q-61 | H14: MD-41
A15: 18208 | B15: 46073 | C15: MD-45 | D15: Filtros Incompletos | E15: Carlos Verdugo | F15: Q-61 | H15: MD-45
A16: 18049 | B16: 46073 | C16: VD-115 | D16: Filtro Completros | E16: Daniel Andrade | F16: Taller | H16: VD-115
A17: 18253 | B17: 46073 | C17: CD-69 | D17: Filtros Completros | E17: Daniel Andrade | F17: Taller | G17: Se cambiaron y se compraron de nuevo el kit de aire motor | H17: CD-69
A18: 18225 | B18: 46077 | C18: CD-87 | D18: Filtro Secador | E18: Carlos Verdugo | F18: Palmucho | H18: CD-87
A19: 18226 | B19: 46077 | C19: VD-29 | D19: Filtros Completos | E19: Manuel Ortiz | F19: Cobquecura | H19: VD-29
A20: 18230 | B20: 46077 | C20: MD-84 | D20: Filtros Completos | F20: Quirihue | H20: MD-84
A21: 18236 | B21: 46078 | C21: MD-55 | D21: Filtro Completros | E21: Bernardo Salinas | F21: Palmucho | H21: MD-55
A22: 18236 | B22: 46078 | C22: MD-67 | D22: Filtro Completros | E22: Bernardo Salinas | F22: Palmucho | H22: MD-67
A23: 18264 | B23: 46078 | C23: VD-118 | D23: Filtro Completros | E23: Daniel Andrade | F23: Taller | H23: VD-118
A24: 18246 | B24: 46079 | C24: MD-62 | D24: Filtro Completros | E24: Marcos Soto | F24: Curico | H24: MD-62
A25: 18302 | B25: 46080 | C25: CD-123 | D25: Filtros Completos | E25: Marcos Soto | F25: Quirihue | H25: CD-123
A26: 18304 | B26: 46080 | C26: CD-121 | D26: Filtros Completos | F26: Cobquecura | H26: CD-121
A27: 18304 | B27: 46080 | C27: CD-120 | D27: Filtros Completos | F27: Cobquecura | H27: CD-120
A28: 18305 | B28: 46080 | C28: MD-94 | D28: Filtros Completos | F28: Cobquecura | H28: MD-94
A29: 18306 | B29: 46080 | C29: CD-140 | D29: Filtros Completos | F29: Cobquecura | H29: CD-140
A30: 18307 | B30: 46080 | C30: MD-26 | D30: Filtros Completos | F30: Cobquecura | H30: MD-26
A31: 18308 | B31: 46080 | C31: MD-95 | D31: Filtros Incompletos | F31: Quirihue | G31: Filtro decantador / Filtro Combustible / Filtro Aceite | H31: MD-95
A32: 18310 | B32: 46080 | C32: VD-124 | D32: Filtros Completos | F32: Cobquecura | H32: VD-124
A33: 18276 | B33: 46080 | C33: CD-125 | D33: Filtros Incompletos | E33: Patricio Novoa | G33: Filtro de combustible / Filtro de Aceite | H33: CD-125
A34: 18280 | B34: 46083 | C34: MD-51 | D34: Filtro Completros | F34: Palmucho | H34: MD-51
A35: 18284 | B35: 46083 | C35: MD-96 | D35: Filtros Completos | E35: Juan Roco | F35: San Carlos | H35: MD-96
A36: 18288 | B36: 46083 | C36: MD-94 | D36: Filtro Completros | F36: Palmucho | H36: MD-94
A37: 18289 | B37: 46083 | C37: MD-98 | D37: Filtros Completros | E37: Roberto Ventura | F37: Q-61 | H37: MD-98
B38: 46083 | C38: VD-88 | D38: Filtros Completos | F38: Palmucho | H38: VD-88
A39: 18322 | B39: 46084 | C39: CD-107 | D39: Filtros Incompletos | E39: Daniel Andrade | F39: Taller | G39: Filtro decantador / Filtro Combustible | H39: CD-107
A40: 18332 | B40: 46085 | C40: CD-86 | D40: Filtros Completos | E40: Marcos Soto | F40: Quirihue | H40: CD-86
A41: 18332 | B41: 46085 | C41: VD-113 | D41: Filtros Completos | E41: Marcos Soto | F41: Quirihue | H41: VD-113
...

Sheet Maestro_Equipos
A1: Maestro de Equipos
A3: Codigo | B3: Tipo Equipo | C3: Familia | D3: Marca | E3: Modelo | F3: Año | G3: Ubicacion | H3: Responsable | I3: Control Base | J3: Frecuencia Base | K3: Promedio Diario | L3: Ultima Fecha Lectura | M3: Ultimo Horometro | N3: Ultimo Kilometraje | O3: Lectura Actual | P3: Ultima Fecha PM | Q3: Ultima PM | R3: Ultima Lectura PM | S3: Costo Mantenciones CLP | T3: Costo Compras PM CLP | U3: Costo Total PM CLP | V3: Estado Operacional | W3: Estado CMMS | X3: Dias a Proxima Mantencion | Y3: Fecha Est. Proxima Mantencion | Z3: Fecha Compra PM | AA3: Fecha Salida Bodega | AB3: Tiempo Compra → Mantención | AC3: Tiempo Bodega → Mantención | AD3: Estado Bodega → Mantención | AE3: Estado Operativo Real | AF3: Prioridad Taller | AG3: Acción Sugerida | AH3: _CompraRequerida | AI3: _OrdenCompra | AJ3: Criticidad
A4: CD-100 | B4: Camión Slurry | C4: Camiones de Ruta | D4: Volkswagen | E4: 26220 | F4: 2008 | G4: =IFERROR(_xlfn.XLOOKUP($A4,tblEquipos[Codigo],tblEquipos[Ubicacion],""),"") -> San Carlos | H4: Juan Espinoza | I4: =IFERROR(VLOOKUP(A4, Equipos!A:J, 9, FALSE), "") -> HORAS | J4: =IFERROR(VLOOKUP(A4, Equipos!A:J, 10, FALSE), "") -> 250 | K4: =IFERROR(IF($I4="KM",ROUND((_xlfn.MAXIFS(tblLecturas[Kilometraje],tblLecturas[Codigo],$A4)-_xlfn.MINIFS(tblLecturas[Kilometraje],tblLecturas[Codigo],$A4))/(MAX(1,_xlfn.MAXIFS(tblLecturas[Fecha],tblLecturas[Codigo],$A4)-_xlfn.MINIFS(tblLecturas[Fecha],tblLecturas[Codigo],$A4))),1),ROUND((_xlfn.MAXIFS(tblLecturas[Horometro],tblLecturas[Codigo],$A4)-_xlfn.MINIFS(tblLecturas[Horometro],tblLecturas[Codigo],$A4))/(MAX(1,_xlfn.MAXIFS(tblLecturas[Fecha],tblLecturas[Codigo],$A4)-_xlfn.MINIFS(tblLecturas[Fecha],tblLecturas[Codigo],$A4))),1)),"") -> 1 | L4: =IFERROR(_xlfn.MAXIFS(tblLecturas[Fecha],tblLecturas[Codigo],$A4),"") -> 46155 | M4: =IFERROR(_xlfn.MAXIFS(Lecturas!$C:$C,Lecturas!$B:$B,$A4,Lecturas!$C:$C,">0"),"") -> 2852 | N4: =IFERROR(_xlfn.MAXIFS(tblLecturas[Kilometraje],tblLecturas[Codigo],$A4,tblLecturas[Kilometraje],">0"),"") -> 158684 | O4: {=IFERROR(IF($I4="KM",LOOKUP(2,1/(Lecturas!$B:$B=$A4)/(Lecturas!$D:$D>0),Lecturas!$D:$D),LOOKUP(2,1/(Lecturas!$B:$B=$A4)/(Lecturas!$C:$C>0),Lecturas!$C:$C)),"")} -> 985 | P4: =IFERROR(_xlfn.MAXIFS(tblMantenciones[Fecha],tblMantenciones[Codigo],tblMaestroEquipos[[#This Row],[Codigo]],tblMantenciones[EsPM],"Sí"),"") -> 46113 | Q4: =IF(_xlfn.MAXIFS(Mantenciones!$D:$D,Mantenciones!$B:$B,A4)=0,"Sin datos de mantención registrado",_xlfn.MAXIFS(Mantenciones!$D:$D,Mantenciones!$B:$B,A4)) -> 2882 | R4: =IFERROR(IF(_xlfn.MAXIFS(Mantenciones!$D:$D,Mantenciones!$B:$B,$A4,Mantenciones!$E:$E,"Sí",Mantenciones!$D:$D,">0")=0,"Sin datos de mantención registrado",_xlfn.MAXIFS(Mantenciones!$D:$D,Mantenciones!$B:$B,$A4,Mantenciones!$E:$E,"Sí",Mantenciones!$D:$D,">0")),"Sin datos de mantención registrado") -> 2882 | S4: =IFERROR(SUMIFS(tblMantenciones[Costo Mantencion CLP],tblMantenciones[Codigo],A4),0) -> 0 | T4: =IFERROR(SUMIFS(tblComprasPM[Costo PM CLP],tblComprasPM[Codigo],tblMaestroEquipos[[#This Row],[Codigo]]),0) -> 199255.98 | U4: =IFERROR(tblMaestroEquipos[[#This Row],[Costo Mantenciones CLP]]+tblMaestroEquipos[[#This Row],[Costo Compras PM CLP]],0) -> 199255.98 | V4: =IFERROR(_xlfn.XLOOKUP(tblMaestroEquipos[[#This Row],[Codigo]],tblEquipos[Codigo],tblEquipos[Estado Base]),"") -> Operativo | W4: =IF(OR(TRIM($V4)="Fuera de Servicio",TRIM($V4)="Fuera de servicio"),"FUERA DE SERVICIO",IF(OR(TRIM($V4)="Taller",TRIM($V4)="En taller",TRIM($V4)="EN TALLER"),"EN TALLER",IF($AD4="PENDIENTE","POR RECIBIR",IF(AND($Z4<>"",$AA4=""),"EN PROCESO",IF(AND(ISNUMBER($X4),$X4<0),"ATRASADA",IF(AND(ISNUMBER($X4),$X4<=30),"PRÓXIMA","AL DÍA")))))) -> AL DÍA | X4: =IF(OR(NOT(ISNUMBER(R4)),NOT(ISNUMBER(J4)),NOT(ISNUMBER(O4))),"", (R4+J4)-O4) -> 2147 | Y4: =IFERROR(IF(OR(tblMaestroEquipos[[#This Row],[Estado Operacional]]="FUERA DE SERVICIO",tblMaestroEquipos[[#This Row],[Ultima Fecha Lectura]]="",tblMaestroEquipos[[#This Row],[Dias a Proxima Mantencion]]=""),"",tblMaestroEquipos[[#This Row],[Ultima Fecha Lectura]]+tblMaestroEquipos[[#This Row],[Dias a Proxima Mantencion]]),"") -> 48302 | Z4: =IFERROR(IF(_xlfn.MINIFS(tblComprasPM[Fecha],tblComprasPM[Codigo],tblMaestroEquipos[[#This Row],[Codigo]])=0,"",_xlfn.MINIFS(tblComprasPM[Fecha],tblComprasPM[Codigo],tblMaestroEquipos[[#This Row],[Codigo]])),"") -> 46085.627 | AA4: =IFERROR(IF(_xlfn.MAXIFS(tblBodega[Fecha],tblBodega[Codigo],tblMaestroEquipos[[#This Row],[Codigo]])=0,"",_xlfn.MAXIFS(tblBodega[Fecha],tblBodega[Codigo],tblMaestroEquipos[[#This Row],[Codigo]])),"") -> 46113 | AB4: =IFERROR(IF(OR(tblMaestroEquipos[[#This Row],[Fecha Compra PM]]="",tblMaestroEquipos[[#This Row],[Fecha Compra PM]]=0),"",IF(OR(tblMaestroEquipos[[#This Row],[Ultima Fecha PM]]="",tblMaestroEquipos[[#This Row],[Ultima Fecha PM]]=0),MAX(0,INT(TODAY())-INT(tblMaestroEquipos[[#This Row],[Fecha Compra PM]])),MAX(0,INT(tblMaestroEquipos[[#This Row],[Ultima Fecha PM]])-INT(tblMaestroEquipos[[#This Row],[Fecha Compra PM]])))),"") -> 28 | AC4: =IFERROR(IF(OR(tblMaestroEquipos[[#This Row],[Fecha Salida Bodega]]="",tblMaestroEquipos[[#This Row],[Fecha Salida Bodega]]=0),"",IF(OR(tblMaestroEquipos[[#This Row],[Ultima Fecha PM]]="",tblMaestroEquipos[[#This Row],[Ultima Fecha PM]]=0),MAX(0,INT(TODAY())-INT(tblMaestroEquipos[[#This Row],[Fecha Salida Bodega]])),MAX(0,INT(tblMaestroEquipos[[#This Row],[Ultima Fecha PM]])-INT(tblMaestroEquipos[[#This Row],[Fecha Salida Bodega]])))),"") -> 0 | AD4: =IF(tblMaestroEquipos[[#This Row],[Fecha Salida Bodega]]="","SIN SALIDA BODEGA",IF(OR(tblMaestroEquipos[[#This Row],[Ultima Fecha PM]]="",tblMaestroEquipos[[#This Row],[Ultima Fecha PM]]<tblMaestroEquipos[[#This Row],[Fecha Salida Bodega]]),"PENDIENTE","CERRADO")) -> CERRADO | AE4: =IF(TRIM(V4)="Fuera de servicio","FUERA DE SERVICIO", IF(OR(TRIM(V4)="Taller",TRIM(V4)="En taller"),"EN TALLER", IF(W4="ATRASADO","ATRASADO", IF(W4="EN PROCESO","EN PROCESO", IF(W4="PRÓXIMO","PRÓXIMO", "OPERATIVO"))))) -> OPERATIVO | AF4: =IF($AE4="ATRASADA",IF($X4<=-15,"CRÍTICA","ALTA"),IF($AE4="PRÓXIMA","MEDIA",IF(OR($AE4="EN PROCESO",$AE4="POR RECIBIR"),"SEGUIMIENTO",IF($AE4="FUERA DE SERVICIO","NO APLICA","BAJA")))) -> BAJA | AG4: =IF($AE4="FUERA DE SERVICIO","No programar compra",IF($AE4="CERRADO","Cerrar ciclo y preparar siguiente PM",IF($AE4="EN PROCESO","Hacer seguimiento al taller y cerrar report",IF($AE4="POR RECIBIR","Acelerar recepción de repuestos",IF($AE4="ATRASADA","Comprar kit PM y coordinar ejecución",IF($AE4="PRÓXIMA","Planificar compra preventiva","Monitorear próximo vencimiento")))))) -> Monitorear próximo vencimiento | AH4: =IF(AND(OR($AE4="ATRASADA",$AE4="PRÓXIMA"),$Z4="",$AA4=""),1,0) -> 0 | AI4: =IF(OR($AH4=0,$Y4=""),"",SUMPRODUCT(($AH$4:$AH$242=1)*(($Y$4:$Y$242<$Y4)+(($Y$4:$Y$242=$Y4)*(ROW($Y$4:$Y$242)<=ROW()))))) | AJ4: =IF(W4="ATRASADA",1,IF(W4="EN PROCESO",2,IF(W4="POR RECIBIR",3,99))) -> 99
A5: CD-102 | B5: Camión Tolva | C5: Camiones de Ruta | D5: Man | E5: TGS 50480 | F5: 2018 | G5: =IFERROR(_xlfn.XLOOKUP($A5,tblEquipos[Codigo],tblEquipos[Ubicacion],""),"") -> San Nicolas | H5: Nelson Garcia | I5: =IFERROR(VLOOKUP(A5, Equipos!A:J, 9, FALSE), "") -> HORAS | J5: =IFERROR(VLOOKUP(A5, Equipos!A:J, 10, FALSE), "") -> 500 | K5: =IFERROR(IF($I5="KM",ROUND((_xlfn.MAXIFS(tblLecturas[Kilometraje],tblLecturas[Codigo],$A5)-_xlfn.MINIFS(tblLecturas[Kilometraje],tblLecturas[Codigo],$A5))/(MAX(1,_xlfn.MAXIFS(tblLecturas[Fecha],tblLecturas[Codigo],$A5)-_xlfn.MINIFS(tblLecturas[Fecha],tblLecturas[Codigo],$A5))),1),ROUND((_xlfn.MAXIFS(tblLecturas[Horometro],tblLecturas[Codigo],$A5)-_xlfn.MINIFS(tblLecturas[Horometro],tblLecturas[Codigo],$A5))/(MAX(1,_xlfn.MAXIFS(tblLecturas[Fecha],tblLecturas[Codigo],$A5)-_xlfn.MINIFS(tblLecturas[Fecha],tblLecturas[Codigo],$A5))),1)),"") -> 4.5 | L5: =IFERROR(_xlfn.MAXIFS(tblLecturas[Fecha],tblLecturas[Codigo],$A5),"") -> 46160 | M5: =IFERROR(_xlfn.MAXIFS(Lecturas!$C:$C,Lecturas!$B:$B,$A5,Lecturas!$C:$C,">0"),"") -> 10633 | N5: =IFERROR(_xlfn.MAXIFS(tblLecturas[Kilometraje],tblLecturas[Codigo],$A5,tblLecturas[Kilometraje],">0"),"") -> 262575 | O5: {=IFERROR(IF($I5="KM",LOOKUP(2,1/(Lecturas!$B:$B=$A5)/(Lecturas!$D:$D>0),Lecturas!$D:$D),LOOKUP(2,1/(Lecturas!$B:$B=$A5)/(Lecturas!$C:$C>0),Lecturas!$C:$C)),"")} -> 10633 | P5: =IFERROR(_xlfn.MAXIFS(tblMantenciones[Fecha],tblMantenciones[Codigo],tblMaestroEquipos[[#This Row],[Codigo]],tblMantenciones[EsPM],"Sí"),"") -> 46197 | Q5: =IF(_xlfn.MAXIFS(Mantenciones!$D:$D,Mantenciones!$B:$B,A5)=0,"Sin datos de mantención registrado",_xlfn.MAXIFS(Mantenciones!$D:$D,Mantenciones!$B:$B,A5)) -> 11042 | R5: =IFERROR(IF(_xlfn.MAXIFS(Mantenciones!$D:$D,Mantenciones!$B:$B,$A5,Mantenciones!$E:$E,"Sí",Mantenciones!$D:$D,">0")=0,"Sin datos de mantención registrado",_xlfn.MAXIFS(Mantenciones!$D:$D,Mantenciones!$B:$B,$A5,Mantenciones!$E:$E,"Sí",Mantenciones!$D:$D,">0")),"Sin datos de mantención registrado") -> 11042 | S5: =IFERROR(SUMIFS(tblMantenciones[Costo Mantencion CLP],tblMantenciones[Codigo],A5),0) -> 0 | T5: =IFERROR(SUMIFS(tblComprasPM[Costo PM CLP],tblComprasPM[Codigo],tblMaestroEquipos[[#This Row],[Codigo]]),0) -> 314826.62 | U5: =IFERROR(tblMaestroEquipos[[#This Row],[Costo Mantenciones CLP]]+tblMaestroEquipos[[#This Row],[Costo Compras PM CLP]],0) -> 314826.62 | V5: =IFERROR(_xlfn.XLOOKUP(tblMaestroEquipos[[#This Row],[Codigo]],tblEquipos[Codigo],tblEquipos[Estado Base]),"") -> Operativo | W5: =IF(OR(TRIM($V5)="Fuera de Servicio",TRIM($V5)="Fuera de servicio"),"FUERA DE SERVICIO",IF(OR(TRIM($V5)="Taller",TRIM($V5)="En taller",TRIM($V5)="EN TALLER"),"EN TALLER",IF($AD5="PENDIENTE","POR RECIBIR",IF(AND($Z5<>"",$AA5=""),"EN PROCESO",IF(AND(ISNUMBER($X5),$X5<0),"ATRASADA",IF(AND(ISNUMBER($X5),$X5<=30),"PRÓXIMA","AL DÍA")))))) -> AL DÍA | X5: =IF(OR(NOT(ISNUMBER(R5)),NOT(ISNUMBER(J5)),NOT(ISNUMBER(O5))),"", (R5+J5)-O5) -> 909 | Y5: =IFERROR(IF(OR(tblMaestroEquipos[[#This Row],[Estado Operacional]]="FUERA DE SERVICIO",tblMaestroEquipos[[#This Row],[Ultima Fecha Lectura]]="",tblMaestroEquipos[[#This Row],[Dias a Proxima Mantencion]]=""),"",tblMaestroEquipos[[#This Row],[Ultima Fecha Lectura]]+tblMaestroEquipos[[#This Row],[Dias a Proxima Mantencion]]),"") -> 47069 | Z5: =IFERROR(IF(_xlfn.MINIFS(tblComprasPM[Fecha],tblComprasPM[Codigo],tblMaestroEquipos[[#This Row],[Codigo]])=0,"",_xlfn.MINIFS(tblComprasPM[Fecha],tblComprasPM[Codigo],tblMaestroEquipos[[#This Row],[Codigo]])),"") -> 46069.447 | AA5: =IFERROR(IF(_xlfn.MAXIFS(tblBodega[Fecha],tblBodega[Codigo],tblMaestroEquipos[[#This Row],[Codigo]])=0,"",_xlfn.MAXIFS(tblBodega[Fecha],tblBodega[Codigo],tblMaestroEquipos[[#This Row],[Codigo]])),"") -> 46174 | AB5: =IFERROR(IF(OR(tblMaestroEquipos[[#This Row],[Fecha Compra PM]]="",tblMaestroEquipos[[#This Row],[Fecha Compra PM]]=0),"",IF(OR(tblMaestroEquipos[[#This Row],[Ultima Fecha PM]]="",tblMaestroEquipos[[#This Row],[Ultima Fecha PM]]=0),MAX(0,INT(TODAY())-INT(tblMaestroEquipos[[#This Row],[Fecha Compra PM]])),MAX(0,INT(tblMaestroEquipos[[#This Row],[Ultima Fecha PM]])-INT(tblMaestroEquipos[[#This Row],[Fecha Compra PM]])))),"") -> 128 | AC5: =IFERROR(IF(OR(tblMaestroEquipos[[#This Row],[Fecha Salida Bodega]]="",tblMaestroEquipos[[#This Row],[Fecha Salida Bodega]]=0),"",IF(OR(tblMaestroEquipos[[#This Row],[Ultima Fecha PM]]="",tblMaestroEquipos[[#This Row],[Ultima Fecha PM]]=0),MAX(0,INT(TODAY())-INT(tblMaestroEquipos[[#This Row],[Fecha Salida Bodega]])),MAX(0,INT(tblMaestroEquipos[[#This Row],[Ultima Fecha PM]])-INT(tblMaestroEquipos[[#This Row],[Fecha Salida Bodega]])))),"") -> 23 | AD5: =IF(tblMaestroEquipos[[#This Row],[Fecha Salida Bodega]]="","SIN SALIDA BODEGA",IF(OR(tblMaestroEquipos[[#This Row],[Ultima Fecha PM]]="",tblMaestroEquipos[[#This Row],[Ultima Fecha PM]]<tblMaestroEquipos[[#This Row],[Fecha Salida Bodega]]),"PENDIENTE","CERRADO")) -> CERRADO | AE5: =IF(TRIM(V5)="Fuera de servicio","FUERA DE SERVICIO", IF(OR(TRIM(V5)="Taller",TRIM(V5)="En taller"),"EN TALLER", IF(W5="ATRASADO","ATRASADO", IF(W5="EN PROCESO","EN PROCESO", IF(W5="PRÓXIMO","PRÓXIMO", "OPERATIVO"))))) -> OPERATIVO | AF5: =IF($AE5="ATRASADA",IF($X5<=-15,"CRÍTICA","ALTA"),IF($AE5="PRÓXIMA","MEDIA",IF(OR($AE5="EN PROCESO",$AE5="POR RECIBIR"),"SEGUIMIENTO",IF($AE5="FUERA DE SERVICIO","NO APLICA","BAJA")))) -> BAJA | AG5: =IF($AE5="FUERA DE SERVICIO","No programar compra",IF($AE5="CERRADO","Cerrar ciclo y preparar siguiente PM",IF($AE5="EN PROCESO","Hacer seguimiento al taller y cerrar report",IF($AE5="POR RECIBIR","Acelerar recepción de repuestos",IF($AE5="ATRASADA","Comprar kit PM y coordinar ejecución",IF($AE5="PRÓXIMA","Planificar compra preventiva","Monitorear próximo vencimiento")))))) -> Monitorear próximo vencimiento | AH5: =IF(AND(OR($AE5="ATRASADA",$AE5="PRÓXIMA"),$Z5="",$AA5=""),1,0) -> 0 | AI5: =IF(OR($AH5=0,$Y5=""),"",SUMPRODUCT(($AH$4:$AH$242=1)*(($Y$4:$Y$242<$Y5)+(($Y$4:$Y$242=$Y5)*(ROW($Y$4:$Y$242)<=ROW()))))) | AJ5: =IF(W5="ATRASADA",1,IF(W5="EN PROCESO",2,IF(W5="POR RECIBIR",3,99))) -> 99
A6: CD-103 | B6: Camión Tolva | C6: Camiones de Ruta | D6: Man | E6: TGS 50480 | F6: 2018 | G6: =IFERROR(_xlfn.XLOOKUP($A6,tblEquipos[Codigo],tblEquipos[Ubicacion],""),"") -> TALLER | H6: Felipe Figueroa | I6: =IFERROR(VLOOKUP(A6, Equipos!A:J, 9, FALSE), "") -> HORAS | J6: =IFERROR(VLOOKUP(A6, Equipos!A:J, 10, FALSE), "") -> 500 | K6: =IFERROR(IF($I6="KM",ROUND((_xlfn.MAXIFS(tblLecturas[Kilometraje],tblLecturas[Codigo],$A6)-_xlfn.MINIFS(tblLecturas[Kilometraje],tblLecturas[Codigo],$A6))/(MAX(1,_xlfn.MAXIFS(tblLecturas[Fecha],tblLecturas[Codigo],$A6)-_xlfn.MINIFS(tblLecturas[Fecha],tblLecturas[Codigo],$A6))),1),ROUND((_xlfn.MAXIFS(tblLecturas[Horometro],tblLecturas[Codigo],$A6)-_xlfn.MINIFS(tblLecturas[Horometro],tblLecturas[Codigo],$A6))/(MAX(1,_xlfn.MAXIFS(tblLecturas[Fecha],tblLecturas[Codigo],$A6)-_xlfn.MINIFS(tblLecturas[Fecha],tblLecturas[Codigo],$A6))),1)),"") -> 0 | L6: =IFERROR(_xlfn.MAXIFS(tblLecturas[Fecha],tblLecturas[Codigo],$A6),"") -> 45056 | M6: =IFERROR(_xlfn.MAXIFS(Lecturas!$C:$C,Lecturas!$B:$B,$A6,Lecturas!$C:$C,">0"),"") -> 5327 | N6: =IFERROR(_xlfn.MAXIFS(tblLecturas[Kilometraje],tblLecturas[Codigo],$A6,tblLecturas[Kilometraje],">0"),"") -> 126893 | O6: {=IFERROR(IF($I6="KM",LOOKUP(2,1/(Lecturas!$B:$B=$A6)/(Lecturas!$D:$D>0),Lecturas!$D:$D),LOOKUP(2,1/(Lecturas!$B:$B=$A6)/(Lecturas!$C:$C>0),Lecturas!$C:$C)),"")} -> 5327 | P6: =IFERROR(_xlfn.MAXIFS(tblMantenciones[Fecha],tblMantenciones[Codigo],tblMaestroEquipos[[#This Row],[Codigo]],tblMantenciones[EsPM],"Sí"),"") -> 45234 | Q6: =IF(_xlfn.MAXIFS(Mantenciones!$D:$D,Mantenciones!$B:$B,A6)=0,"Sin datos de mantención registrado",_xlfn.MAXIFS(Mantenciones!$D:$D,Mantenciones!$B:$B,A6)) -> 5942 | R6: =IFERROR(IF(_xlfn.MAXIFS(Mantenciones!$D:$D,Mantenciones!$B:$B,$A6,Mantenciones!$E:$E,"Sí",Mantenciones!$D:$D,">0")=0,"Sin datos de mantención registrado",_xlfn.MAXIFS(Mantenciones!$D:$D,Mantenciones!$B:$B,$A6,Mantenciones!$E:$E,"Sí",Mantenciones!$D:$D,">0")),"Sin datos de mantención registrado") -> 5942 | S6: =IFERROR(SUMIFS(tblMantenciones[Costo Mantencion CLP],tblMantenciones[Codigo],A6),0) -> 0 | T6: =IFERROR(SUMIFS(tblComprasPM[Costo PM CLP],tblComprasPM[Codigo],tblMaestroEquipos[[#This Row],[Codigo]]),0) -> 0 | U6: =IFERROR(tblMaestroEquipos[[#This Row],[Costo Mantenciones CLP]]+tblMaestroEquipos[[#This Row],[Costo Compras PM CLP]],0) -> 0 | V6: =IFERROR(_xlfn.XLOOKUP(tblMaestroEquipos[[#This Row],[Codigo]],tblEquipos[Codigo],tblEquipos[Estado Base]),"") -> Fuera de Servicio | W6: =IF(OR(TRIM($V6)="Fuera de Servicio",TRIM($V6)="Fuera de servicio"),"FUERA DE SERVICIO",IF(OR(TRIM($V6)="Taller",TRIM($V6)="En taller",TRIM($V6)="EN TALLER"),"EN TALLER",IF($AD6="PENDIENTE","POR RECIBIR",IF(AND($Z6<>"",$AA6=""),"EN PROCESO",IF(AND(ISNUMBER($X6),$X6<0),"ATRASADA",IF(AND(ISNUMBER($X6),$X6<=30),"PRÓXIMA","AL DÍA")))))) -> FUERA DE SERVICIO | X6: =IF(OR(NOT(ISNUMBER(R6)),NOT(ISNUMBER(J6)),NOT(ISNUMBER(O6))),"", (R6+J6)-O6) -> 1115 | Y6: =IFERROR(IF(OR(tblMaestroEquipos[[#This Row],[Estado Operacional]]="FUERA DE SERVICIO",tblMaestroEquipos[[#This Row],[Ultima Fecha Lectura]]="",tblMaestroEquipos[[#This Row],[Dias a Proxima Mantencion]]=""),"",tblMaestroEquipos[[#This Row],[Ultima Fecha Lectura]]+tblMaestroEquipos[[#This Row],[Dias a Proxima Mantencion]]),"") | Z6: =IFERROR(IF(_xlfn.MINIFS(tblComprasPM[Fecha],tblComprasPM[Codigo],tblMaestroEquipos[[#This Row],[Codigo]])=0,"",_xlfn.MINIFS(tblComprasPM[Fecha],tblComprasPM[Codigo],tblMaestroEquipos[[#This Row],[Codigo]])),"") | AA6: =IFERROR(IF(_xlfn.MAXIFS(tblBodega[Fecha],tblBodega[Codigo],tblMaestroEquipos[[#This Row],[Codigo]])=0,"",_xlfn.MAXIFS(tblBodega[Fecha],tblBodega[Codigo],tblMaestroEquipos[[#This Row],[Codigo]])),"") | AB6: =IFERROR(IF(OR(tblMaestroEquipos[[#This Row],[Fecha Compra PM]]="",tblMaestroEquipos[[#This Row],[Fecha Compra PM]]=0),"",IF(OR(tblMaestroEquipos[[#This Row],[Ultima Fecha PM]]="",tblMaestroEquipos[[#This Row],[Ultima Fecha PM]]=0),MAX(0,INT(TODAY())-INT(tblMaestroEquipos[[#This Row],[Fecha Compra PM]])),MAX(0,INT(tblMaestroEquipos[[#This Row],[Ultima Fecha PM]])-INT(tblMaestroEquipos[[#This Row],[Fecha Compra PM]])))),"") | AC6: =IFERROR(IF(OR(tblMaestroEquipos[[#This Row],[Fecha Salida Bodega]]="",tblMaestroEquipos[[#This Row],[Fecha Salida Bodega]]=0),"",IF(OR(tblMaestroEquipos[[#This Row],[Ultima Fecha PM]]="",tblMaestroEquipos[[#This Row],[Ultima Fecha PM]]=0),MAX(0,INT(TODAY())-INT(tblMaestroEquipos[[#This Row],[Fecha Salida Bodega]])),MAX(0,INT(tblMaestroEquipos[[#This Row],[Ultima Fecha PM]])-INT(tblMaestroEquipos[[#This Row],[Fecha Salida Bodega]])))),"") | AD6: =IF(tblMaestroEquipos[[#This Row],[Fecha Salida Bodega]]="","SIN SALIDA BODEGA",IF(OR(tblMaestroEquipos[[#This Row],[Ultima Fecha PM]]="",tblMaestroEquipos[[#This Row],[Ultima Fecha PM]]<tblMaestroEquipos[[#This Row],[Fecha Salida Bodega]]),"PENDIENTE","CERRADO")) -> SIN SALIDA BODEGA | AE6: =IF(TRIM(V6)="Fuera de servicio","FUERA DE SERVICIO", IF(OR(TRIM(V6)="Taller",TRIM(V6)="En taller"),"EN TALLER", IF(W6="ATRASADO","ATRASADO", IF(W6="EN PROCESO","EN PROCESO", IF(W6="PRÓXIMO","PRÓXIMO", "OPERATIVO"))))) -> FUERA DE SERVICIO | AF6: =IF($AE6="ATRASADA",IF($X6<=-15,"CRÍTICA","ALTA"),IF($AE6="PRÓXIMA","MEDIA",IF(OR($AE6="EN PROCESO",$AE6="POR RECIBIR"),"SEGUIMIENTO",IF($AE6="FUERA DE SERVICIO","NO APLICA","BAJA")))) -> NO APLICA | AG6: =IF($AE6="FUERA DE SERVICIO","No programar compra",IF($AE6="CERRADO","Cerrar ciclo y preparar siguiente PM",IF($AE6="EN PROCESO","Hacer seguimiento al taller y cerrar report",IF($AE6="POR RECIBIR","Acelerar recepción de repuestos",IF($AE6="ATRASADA","Comprar kit PM y coordinar ejecución",IF($AE6="PRÓXIMA","Planificar compra preventiva","Monitorear próximo vencimiento")))))) -> No programar compra | AH6: =IF(AND(OR($AE6="ATRASADA",$AE6="PRÓXIMA"),$Z6="",$AA6=""),1,0) -> 0 | AI6: =IF(OR($AH6=0,$Y6=""),"",SUMPRODUCT(($AH$4:$AH$242=1)*(($Y$4:$Y$242<$Y6)+(($Y$4:$Y$242=$Y6)*(ROW($Y$4:$Y$242)<=ROW()))))) | AJ6: =IF(W6="ATRASADA",1,IF(W6="EN PROCESO",2,IF(W6="POR RECIBIR",3,99))) -> 99
A7: CD-104 | B7: Camión Tolva | C7: Camiones de Ruta | D7: Man | E7: TGS 50480 | F7: 2019 | G7: =IFERROR(_xlfn.XLOOKUP($A7,tblEquipos[Codigo],tblEquipos[Ubicacion],""),"") -> Emergencias Curico | H7: Nelson Cancino | I7: =IFERROR(VLOOKUP(A7, Equipos!A:J, 9, FALSE), "") -> HORAS | J7: =IFERROR(VLOOKUP(A7, Equipos!A:J, 10, FALSE), "") -> 250 | K7: =IFERROR(IF($I7="KM",ROUND((_xlfn.MAXIFS(tblLecturas[Kilometraje],tblLecturas[Codigo],$A7)-_xlfn.MINIFS(tblLecturas[Kilometraje],tblLecturas[Codigo],$A7))/(MAX(1,_xlfn.MAXIFS(tblLecturas[Fecha],tblLecturas[Codigo],$A7)-_xlfn.MINIFS(tblLecturas[Fecha],tblLecturas[Codigo],$A7))),1),ROUND((_xlfn.MAXIFS(tblLecturas[Horometro],tblLecturas[Codigo],$A7)-_xlfn.MINIFS(tblLecturas[Horometro],tblLecturas[Codigo],$A7))/(MAX(1,_xlfn.MAXIFS(tblLecturas[Fecha],tblLecturas[Codigo],$A7)-_xlfn.MINIFS(tblLecturas[Fecha],tblLecturas[Codigo],$A7))),1)),"") -> 0 | L7: =IFERROR(_xlfn.MAXIFS(tblLecturas[Fecha],tblLecturas[Codigo],$A7),"") -> 46114 | M7: =IFERROR(_xlfn.MAXIFS(Lecturas!$C:$C,Lecturas!$B:$B,$A7,Lecturas!$C:$C,">0"),"") -> 8820 | N7: =IFERROR(_xlfn.MAXIFS(tblLecturas[Kilometraje],tblLecturas[Codigo],$A7,tblLecturas[Kilometraje],">0"),"") -> 261250 | O7: {=IFERROR(IF($I7="KM",LOOKUP(2,1/(Lecturas!$B:$B=$A7)/(Lecturas!$D:$D>0),Lecturas!$D:$D),LOOKUP(2,1/(Lecturas!$B:$B=$A7)/(Lecturas!$C:$C>0),Lecturas!$C:$C)),"")} -> 8820 | P7: =IFERROR(_xlfn.MAXIFS(tblMantenciones[Fecha],tblMantenciones[Codigo],tblMaestroEquipos[[#This Row],[Codigo]],tblMantenciones[EsPM],"Sí"),"") -> 46175 | Q7: =IF(_xlfn.MAXIFS(Mantenciones!$D:$D,Mantenciones!$B:$B,A7)=0,"Sin datos de mantención registrado",_xlfn.MAXIFS(Mantenciones!$D:$D,Mantenciones!$B:$B,A7)) -> 9025 | R7: =IFERROR(IF(_xlfn.MAXIFS(Mantenciones!$D:$D,Mantenciones!$B:$B,$A7,Mantenciones!$E:$E,"Sí",Mantenciones!$D:$D,">0")=0,"Sin datos de mantención registrado",_xlfn.MAXIFS(Mantenciones!$D:$D,Mantenciones!$B:$B,$A7,Mantenciones!$E:$E,"Sí",Mantenciones!$D:$D,">0")),"Sin datos de mantención registrado") -> 9025 | S7: =IFERROR(SUMIFS(tblMantenciones[Costo Mantencion CLP],tblMantenciones[Codigo],A7),0) -> 0 | T7: =IFERROR(SUMIFS(tblComprasPM[Costo PM CLP],tblComprasPM[Codigo],tblMaestroEquipos[[#This Row],[Codigo]]),0) -> 314826.62 | U7: =IFERROR(tblMaestroEquipos[[#This Row],[Costo Mantenciones CLP]]+tblMaestroEquipos[[#This Row],[Costo Compras PM CLP]],0) -> 314826.62 | V7: =IFERROR(_xlfn.XLOOKUP(tblMaestroEquipos[[#This Row],[Codigo]],tblEquipos[Codigo],tblEquipos[Estado Base]),"") -> Operativo | W7: =IF(OR(TRIM($V7)="Fuera de Servicio",TRIM($V7)="Fuera de servicio"),"FUERA DE SERVICIO",IF(OR(TRIM($V7)="Taller",TRIM($V7)="En taller",TRIM($V7)="EN TALLER"),"EN TALLER",IF($AD7="PENDIENTE","POR RECIBIR",IF(AND($Z7<>"",$AA7=""),"EN PROCESO",IF(AND(ISNUMBER($X7),$X7<0),"ATRASADA",IF(AND(ISNUMBER($X7),$X7<=30),"PRÓXIMA","AL DÍA")))))) -> AL DÍA | X7: =IF(OR(NOT(ISNUMBER(R7)),NOT(ISNUMBER(J7)),NOT(ISNUMBER(O7))),"", (R7+J7)-O7) -> 455 | Y7: =IFERROR(IF(OR(tblMaestroEquipos[[#This Row],[Estado Operacional]]="FUERA DE SERVICIO",tblMaestroEquipos[[#This Row],[Ultima Fecha Lectura]]="",tblMaestroEquipos[[#This Row],[Dias a Proxima Mantencion]]=""),"",tblMaestroEquipos[[#This Row],[Ultima Fecha Lectura]]+tblMaestroEquipos[[#This Row],[Dias a Proxima Mantencion]]),"") -> 46569 | Z7: =IFERROR(IF(_xlfn.MINIFS(tblComprasPM[Fecha],tblComprasPM[Codigo],tblMaestroEquipos[[#This Row],[Codigo]])=0,"",_xlfn.MINIFS(tblComprasPM[Fecha],tblComprasPM[Codigo],tblMaestroEquipos[[#This Row],[Codigo]])),"") -> 46069.447 | AA7: =IFERROR(IF(_xlfn.MAXIFS(tblBodega[Fecha],tblBodega[Codigo],tblMaestroEquipos[[#This Row],[Codigo]])=0,"",_xlfn.MAXIFS(tblBodega[Fecha],tblBodega[Codigo],tblMaestroEquipos[[#This Row],[Codigo]])),"") -> 46168 | AB7: =IFERROR(IF(OR(tblMaestroEquipos[[#This Row],[Fecha Compra PM]]="",tblMaestroEquipos[[#This Row],[Fecha Compra PM]]=0),"",IF(OR(tblMaestroEquipos[[#This Row],[Ultima Fecha PM]]="",tblMaestroEquipos[[#This Row],[Ultima Fecha PM]]=0),MAX(0,INT(TODAY())-INT(tblMaestroEquipos[[#This Row],[Fecha Compra PM]])),MAX(0,INT(tblMaestroEquipos[[#This Row],[Ultima Fecha PM]])-INT(tblMaestroEquipos[[#This Row],[Fecha Compra PM]])))),"") -> 106 | AC7: =IFERROR(IF(OR(tblMaestroEquipos[[#This Row],[Fecha Salida Bodega]]="",tblMaestroEquipos[[#This Row],[Fecha Salida Bodega]]=0),"",IF(OR(tblMaestroEquipos[[#This Row],[Ultima Fecha PM]]="",tblMaestroEquipos[[#This Row],[Ultima Fecha PM]]=0),MAX(0,INT(TODAY())-INT(tblMaestroEquipos[[#This Row],[Fecha Salida Bodega]])),MAX(0,INT(tblMaestroEquipos[[#This Row],[Ultima Fecha PM]])-INT(tblMaestroEquipos[[#This Row],[Fecha Salida Bodega]])))),"") -> 7 | AD7: =IF(tblMaestroEquipos[[#This Row],[Fecha Salida Bodega]]="","SIN SALIDA BODEGA",IF(OR(tblMaestroEquipos[[#This Row],[Ultima Fecha PM]]="",tblMaestroEquipos[[#This Row],[Ultima Fecha PM]]<tblMaestroEquipos[[#This Row],[Fecha Salida Bodega]]),"PENDIENTE","CERRADO")) -> CERRADO | AE7: =IF(TRIM(V7)="Fuera de servicio","FUERA DE SERVICIO", IF(OR(TRIM(V7)="Taller",TRIM(V7)="En taller"),"EN TALLER", IF(W7="ATRASADO","ATRASADO", IF(W7="EN PROCESO","EN PROCESO", IF(W7="PRÓXIMO","PRÓXIMO", "OPERATIVO"))))) -> OPERATIVO | AF7: =IF($AE7="ATRASADA",IF($X7<=-15,"CRÍTICA","ALTA"),IF($AE7="PRÓXIMA","MEDIA",IF(OR($AE7="EN PROCESO",$AE7="POR RECIBIR"),"SEGUIMIENTO",IF($AE7="FUERA DE SERVICIO","NO APLICA","BAJA")))) -> BAJA | AG7: =IF($AE7="FUERA DE SERVICIO","No programar compra",IF($AE7="CERRADO","Cerrar ciclo y preparar siguiente PM",IF($AE7="EN PROCESO","Hacer seguimiento al taller y cerrar report",IF($AE7="POR RECIBIR","Acelerar recepción de repuestos",IF($AE7="ATRASADA","Comprar kit PM y coordinar ejecución",IF($AE7="PRÓXIMA","Planificar compra preventiva","Monitorear próximo vencimiento")))))) -> Monitorear próximo vencimiento | AH7: =IF(AND(OR($AE7="ATRASADA",$AE7="PRÓXIMA"),$Z7="",$AA7=""),1,0) -> 0 | AI7: =IF(OR($AH7=0,$Y7=""),"",SUMPRODUCT(($AH$4:$AH$242=1)*(($Y$4:$Y$242<$Y7)+(($Y$4:$Y$242=$Y7)*(ROW($Y$4:$Y$242)<=ROW()))))) | AJ7: =IF(W7="ATRASADA",1,IF(W7="EN PROCESO",2,IF(W7="POR RECIBIR",3,99))) -> 99
A8: CD-105 | B8: Camión Tolva | C8: Camiones de Ruta | D8: Man | E8: TGS 50480 | F8: 2018 | G8: =IFERROR(_xlfn.XLOOKUP($A8,tblEquipos[Codigo],tblEquipos[Ubicacion],""),"") -> Palmucho | H8: Jose Andaur | I8: =IFERROR(VLOOKUP(A8, Equipos!A:J, 9, FALSE), "") -> HORAS | J8: =IFERROR(VLOOKUP(A8, Equipos!A:J, 10, FALSE), "") -> 500 | K8: =IFERROR(IF($I8="KM",ROUND((_xlfn.MAXIFS(tblLecturas[Kilometraje],tblLecturas[Codigo],$A8)-_xlfn.MINIFS(tblLecturas[Kilometraje],tblLecturas[Codigo],$A8))/(MAX(1,_xlfn.MAXIFS(tblLecturas[Fecha],tblLecturas[Codigo],$A8)-_xlfn.MINIFS(tblLecturas[Fecha],tblLecturas[Codigo],$A8))),1),ROUND((_xlfn.MAXIFS(tblLecturas[Horometro],tblLecturas[Codigo],$A8)-_xlfn.MINIFS(tblLecturas[Horometro],tblLecturas[Codigo],$A8))/(MAX(1,_xlfn.MAXIFS(tblLecturas[Fecha],tblLecturas[Codigo],$A8)-_xlfn.MINIFS(tblLecturas[Fecha],tblLecturas[Codigo],$A8))),1)),"") -> 6.2 | L8: =IFERROR(_xlfn.MAXIFS(tblLecturas[Fecha],tblLecturas[Codigo],$A8),"") -> 46142 | M8: =IFERROR(_xlfn.MAXIFS(Lecturas!$C:$C,Lecturas!$B:$B,$A8,Lecturas!$C:$C,">0"),"") -> 10821 | N8: =IFERROR(_xlfn.MAXIFS(tblLecturas[Kilometraje],tblLecturas[Codigo],$A8,tblLecturas[Kilometraje],">0"),"") -> 262956 | O8: {=IFERROR(IF($I8="KM",LOOKUP(2,1/(Lecturas!$B:$B=$A8)/(Lecturas!$D:$D>0),Lecturas!$D:$D),LOOKUP(2,1/(Lecturas!$B:$B=$A8)/(Lecturas!$C:$C>0),Lecturas!$C:$C)),"")} -> 10821 | P8: =IFERROR(_xlfn.MAXIFS(tblMantenciones[Fecha],tblMantenciones[Codigo],tblMaestroEquipos[[#This Row],[Codigo]],tblMantenciones[EsPM],"Sí"),"") -> 46127 | Q8: =IF(_xlfn.MAXIFS(Mantenciones!$D:$D,Mantenciones!$B:$B,A8)=0,"Sin datos de mantención registrado",_xlfn.MAXIFS(Mantenciones!$D:$D,Mantenciones!$B:$B,A8)) -> 10738 | R8: =IFERROR(IF(_xlfn.MAXIFS(Mantenciones!$D:$D,Mantenciones!$B:$B,$A8,Mantenciones!$E:$E,"Sí",Mantenciones!$D:$D,">0")=0,"Sin datos de mantención registrado",_xlfn.MAXIFS(Mantenciones!$D:$D,Mantenciones!$B:$B,$A8,Mantenciones!$E:$E,"Sí",Mantenciones!$D:$D,">0")),"Sin datos de mantención registrado") -> 10738 | S8: =IFERROR(SUMIFS(tblMantenciones[Costo Mantencion CLP],tblMantenciones[Codigo],A8),0) -> 0 | T8: =IFERROR(SUMIFS(tblComprasPM[Costo PM CLP],tblComprasPM[Codigo],tblMaestroEquipos[[#This Row],[Codigo]]),0) -> 50277.864 | U8: =IFERROR(tblMaestroEquipos[[#This Row],[Costo Mantenciones CLP]]+tblMaestroEquipos[[#This Row],[Costo Compras PM CLP]],0) -> 50277.864 | V8: =IFERROR(_xlfn.XLOOKUP(tblMaestroEquipos[[#This Row],[Codigo]],tblEquipos[Codigo],tblEquipos[Estado Base]),"") -> Operativo | W8: =IF(OR(TRIM($V8)="Fuera de Servicio",TRIM($V8)="Fuera de servicio"),"FUERA DE SERVICIO",IF(OR(TRIM($V8)="Taller",TRIM($V8)="En taller",TRIM($V8)="EN TALLER"),"EN TALLER",IF($AD8="PENDIENTE","POR RECIBIR",IF(AND($Z8<>"",$AA8=""),"EN PROCESO",IF(AND(ISNUMBER($X8),$X8<0),"ATRASADA",IF(AND(ISNUMBER($X8),$X8<=30),"PRÓXIMA","AL DÍA")))))) -> AL DÍA | X8: =IF(OR(NOT(ISNUMBER(R8)),NOT(ISNUMBER(J8)),NOT(ISNUMBER(O8))),"", (R8+J8)-O8) -> 417 | Y8: =IFERROR(IF(OR(tblMaestroEquipos[[#This Row],[Estado Operacional]]="FUERA DE SERVICIO",tblMaestroEquipos[[#This Row],[Ultima Fecha Lectura]]="",tblMaestroEquipos[[#This Row],[Dias a Proxima Mantencion]]=""),"",tblMaestroEquipos[[#This Row],[Ultima Fecha Lectura]]+tblMaestroEquipos[[#This Row],[Dias a Proxima Mantencion]]),"") -> 46559 | Z8: =IFERROR(IF(_xlfn.MINIFS(tblComprasPM[Fecha],tblComprasPM[Codigo],tblMaestroEquipos[[#This Row],[Codigo]])=0,"",_xlfn.MINIFS(tblComprasPM[Fecha],tblComprasPM[Codigo],tblMaestroEquipos[[#This Row],[Codigo]])),"") -> 46069.447 | AA8: =IFERROR(IF(_xlfn.MAXIFS(tblBodega[Fecha],tblBodega[Codigo],tblMaestroEquipos[[#This Row],[Codigo]])=0,"",_xlfn.MAXIFS(tblBodega[Fecha],tblBodega[Codigo],tblMaestroEquipos[[#This Row],[Codigo]])),"") -> 46105 | AB8: =IFERROR(IF(OR(tblMaestroEquipos[[#This Row],[Fecha Compra PM]]="",tblMaestroEquipos[[#This Row],[Fecha Compra PM]]=0),"",IF(OR(tblMaestroEquipos[[#This Row],[Ultima Fecha PM]]="",tblMaestroEquipos[[#This Row],[Ultima Fecha PM]]=0),MAX(0,INT(TODAY())-INT(tblMaestroEquipos[[#This Row],[Fecha Compra PM]])),MAX(0,INT(tblMaestroEquipos[[#This Row],[Ultima Fecha PM]])-INT(tblMaestroEquipos[[#This Row],[Fecha Compra PM]])))),"") -> 58 | AC8: =IFERROR(IF(OR(tblMaestroEquipos[[#This Row],[Fecha Salida Bodega]]="",tblMaestroEquipos[[#This Row],[Fecha Salida Bodega]]=0),"",IF(OR(tblMaestroEquipos[[#This Row],[Ultima Fecha PM]]="",tblMaestroEquipos[[#This Row],[Ultima Fecha PM]]=0),MAX(0,INT(TODAY())-INT(tblMaestroEquipos[[#This Row],[Fecha Salida Bodega]])),MAX(0,INT(tblMaestroEquipos[[#This Row],[Ultima Fecha PM]])-INT(tblMaestroEquipos[[#This Row],[Fecha Salida Bodega]])))),"") -> 22 | AD8: =IF(tblMaestroEquipos[[#This Row],[Fecha Salida Bodega]]="","SIN SALIDA BODEGA",IF(OR(tblMaestroEquipos[[#This Row],[Ultima Fecha PM]]="",tblMaestroEquipos[[#This Row],[Ultima Fecha PM]]<tblMaestroEquipos[[#This Row],[Fecha Salida Bodega]]),"PENDIENTE","CERRADO")) -> CERRADO | AE8: =IF(TRIM(V8)="Fuera de servicio","FUERA DE SERVICIO", IF(OR(TRIM(V8)="Taller",TRIM(V8)="En taller"),"EN TALLER", IF(W8="ATRASADO","ATRASADO", IF(W8="EN PROCESO","EN PROCESO", IF(W8="PRÓXIMO","PRÓXIMO", "OPERATIVO"))))) -> OPERATIVO | AF8: =IF($AE8="ATRASADA",IF($X8<=-15,"CRÍTICA","ALTA"),IF($AE8="PRÓXIMA","MEDIA",IF(OR($AE8="EN PROCESO",$AE8="POR RECIBIR"),"SEGUIMIENTO",IF($AE8="FUERA DE SERVICIO","NO APLICA","BAJA")))) -> BAJA | AG8: =IF($AE8="FUERA DE SERVICIO","No programar compra",IF($AE8="CERRADO","Cerrar ciclo y preparar siguiente PM",IF($AE8="EN PROCESO","Hacer seguimiento al taller y cerrar report",IF($AE8="POR RECIBIR","Acelerar recepción de repuestos",IF($AE8="ATRASADA","Comprar kit PM y coordinar ejecución",IF($AE8="PRÓXIMA","Planificar compra preventiva","Monitorear próximo vencimiento")))))) -> Monitorear próximo vencimiento | AH8: =IF(AND(OR($AE8="ATRASADA",$AE8="PRÓXIMA"),$Z8="",$AA8=""),1,0) -> 0 | AI8: =IF(OR($AH8=0,$Y8=""),"",SUMPRODUCT(($AH$4:$AH$242=1)*(($Y$4:$Y$242<$Y8)+(($Y$4:$Y$242=$Y8)*(ROW($Y$4:$Y$242)<=ROW()))))) | AJ8: =IF(W8="ATRASADA",1,IF(W8="EN PROCESO",2,IF(W8="POR RECIBIR",3,99))) -> 99
