Workbook

Sheet Equipos
A1: EQUIPOS (EDITABLE)
A3: Codigo | B3: Tipo Equipo | C3: Marca | D3: Modelo | E3: Año | F3: Ubicacion | G3: Responsable | H3: Estado Base | I3: Control Base | J3: Frecuencia Base | K3: Promedio Diario
A4: CD-100 | B4: Camión Slurry | C4: Volkswagen | D4: 26220 | E4: 2008 | F4: Q-459 | G4: Juan Espinoza | H4: Operativo | I4: HORAS | J4: 250 | K4: 0
A5: CD-102 | B5: Camión Tolva | C5: Man | D5: TGS 50480 | E5: 2018 | F5: RETIRO | G5: Nelson Garcia | H5: Operativo | I5: HORAS | J5: 250 | K5: 6.54
A6: CD-103 | B6: Camión Tolva | C6: Man | D6: TGS 50480 | E6: 2018 | F6: TALLER | G6: Felipe Figueroa | H6: Fuera de Servicio | I6: HORAS | J6: 250
A7: CD-104 | B7: Camión Tolva | C7: Man | D7: TGS 50480 | E7: 2019 | F7: Curicó | G7: Nelson Omar Cancino Arellano | H7: Operativo | I7: HORAS | J7: 250 | K7: 215.17
A8: CD-105 | B8: Camión Tolva | C8: Man | D8: TGS 50480 | E8: 2018 | F8: Palmucho | G8: Eugenio Antonio Hormazabal Cornejo | H8: Operativo | I8: HORAS | J8: 250 | K8: 97.16
A9: CD-106 | B9: Camión Tolva | C9: Man | D9: TGS 50480 | E9: 2019 | F9: Taller | G9: Eugenio Hormazabal | H9: Operativo | I9: HORAS | J9: 250 | K9: 120.58
A10: CD-107 | B10: Camión Tolva | C10: Man | D10: TGS 50480 | E10: 2019 | F10: San Nicolas | G10: Cesar Vergara | H10: Operativo | I10: HORAS | J10: 250 | K10: 147.06
A11: CD-108 | B11: Camión Slurry | C11: International | D11: 7600 | E11: 2008 | F11: Q-459 | G11: Ivo Garrido | H11: Operativo | I11: HORAS | J11: 250 | K11: 0
A12: CD-109 | B12: Camión Plano | C12: Hino | D12: XZU 6.5 DCAB | E12: 2012 | F12: PALMUCHO | G12: Washinton Sanzana | H12: Operativo | I12: HORAS | J12: 250 | K12: 102.86
A13: CD-110 | B13: Camión Plano | C13: Jac | D13: Urban HFC1050K | E13: 2015 | F13: RETIRO | G13: No identificado | H13: Operativo | I13: HORAS | J13: 250 | K13: 70.85
A14: CD-111 | B14: Camión Plano | C14: Mercedes Benz | D14: Atego 1315 48 | E14: 2007 | F14: TALLER | G14: Sin asignar | H14: Fuera de Servicio | I14: HORAS | J14: 250
A15: CD-112 | B15: Camión Pintura | C15: No hay info | D15: No hay info | E15: No hay info | F15: TALLER | G15: Sin asignar | H15: Fuera de Servicio | I15: HORAS | J15: 250
A16: CD-113 | B16: Camión Imprimador | C16: Volkswagen | D16: 17180M | E16: 2011 | F16: RETIRO | G16: Nector Muñoz | H16: Operativo | I16: HORAS | J16: 250 | K16: 0
A17: CD-114 | B17: Camión Imprimador | C17: Freightliner | D17: M2 112 | E17: 1998 | F17: TALLER | G17: Sin asignar | H17: Operativo | I17: HORAS | J17: 250 | K17: 2.71
A18: CD-115 | B18: Tracto Camión | C18: Mercedes Benz | D18: LS 1634 45 | E18: 2011 | F18: TALLER | G18: Manuel Pacheco | H18: Operativo | I18: HORAS | J18: 250 | K18: 391.03
A19: CD-116 | B19: Camión Plano | C19: Wolkswagen | D19: 9150E | E19: 2012 | F19: Villaseca | G19: Nicolas Antonio Rivera Astudillo | H19: Operativo | I19: HORAS | J19: 250 | K19: 0
A20: CD-117 | B20: Camión Slurry | C20: No hay info | D20: No hay info | E20: No hay info | F20: TALLER | G20: Sin asignar | H20: Fuera de Servicio | I20: HORAS | J20: 250 | K20: 0
A21: CD-118 | B21: Camión Plano | C21: Freightliner | D21: M2 106 | E21: 2010 | F21: TALLER | G21: Carlos Vasquez | H21: Operativo | I21: HORAS | J21: 250 | K21: 292.62
A22: CD-119 | B22: Camión Combustible | C22: Hino | D22: GH8JMTA | E22: 2013 | F22: San Carlos | G22: Nector Aldo Muñoz Rivera | H22: Operativo | I22: HORAS | J22: 250 | K22: 5.15
A23: CD-120 | B23: Camión Tolva | C23: Man | D23: TGS 40400 BB | E23: 2024 | F23: TALLER | G23: Pablo Torres | H23: Operativo | I23: HORAS | J23: 250 | K23: 121.61
A24: CD-121 | B24: Camión Tolva | C24: Man | D24: TGS 40400 BB | E24: 2024 | F24: RETIRO | G24: Chandor Ruiz | H24: Operativo | I24: HORAS | J24: 250 | K24: 105.37
A25: CD-122 | B25: Camión Tolva | C25: Man | D25: TGS 40400 BB | E25: 2024 | F25: RETIRO | G25: Renan Aguilera | H25: Operativo | I25: HORAS | J25: 250 | K25: 1.36
A26: CD-123 | B26: Camión Tolva | C26: Man | D26: TGS 40400 BB | E26: 2024 | F26: Ninhue | G26: Wilson Salazar | H26: Operativo | I26: HORAS | J26: 250 | K26: 42.24
A27: CD-124 | B27: Camión Tolva | C27: Man | D27: TGS 40400 BB | E27: 2024 | H27: Fuera de Servicio | I27: HORAS | J27: 250 | K27: 0
A28: CD-125 | B28: Camión Maxus | C28: Maxus | D28: C35 2.0 | E28: 2023 | F28: Oficina Central | G28: Patricio Alfredo Mora Mora | H28: Operativo | I28: HORAS | J28: 250 | K28: 259.61
A29: CD-126 | B29: Camión Maxus | C29: Maxus | D29: C35 2.0 | E29: 2023 | F29: QUEUCO | G29: Manuel Piñaleo | H29: Operativo | I29: HORAS | J29: 250
A30: CD-127 | B30: Camión Pluma | C30: International | D30: 4300 | E30: 2012 | F30: Oficina Central | G30: Osvaldo Andres Faundez Vasquez | H30: Operativo | I30: HORAS | J30: 250 | K30: 127.61
A31: CD-128 | B31: Camión slurry | C31: Mack | D31: GU 813 | E31: 2012 | F31: Retiro | G31: Marco Calderara | H31: Operativo | I31: HORAS | J31: 250 | K31: 24.84
A32: CD-129 | B32: Camión Aljibe | C32: Mack | D32: GU 813 | E32: 2012 | F32: TALLER | G32: Sin asignar | H32: Fuera de Servicio | I32: HORAS | J32: 250
A33: CD-130 | B33: Camión Tolva | C33: Renault | D33: K480 | E33: 2021 | F33: TALLER | G33: Sin asignar | H33: Fuera de Servicio | I33: HORAS | J33: 250 | K33: 58.71
A34: CD-131 | B34: Camión Tolva | C34: Renault | D34: K480 | E34: 2021 | F34: TALLER | G34: Sin asignar | H34: Fuera de Servicio | I34: HORAS | J34: 250 | K34: 275
A35: CD-132 | B35: Camión Tolva | C35: Renault | D35: K480 | E35: 2021 | F35: Palmucho | G35: Cesar Alonso Vergara Pezoa | H35: Operativo | I35: HORAS | J35: 250 | K35: 168.21
A36: CD-133 | B36: Camión Plano | C36: International | D36: 7400 | E36: 2010 | F36: TALLER | G36: Sin asignar | H36: Fuera de Servicio | I36: HORAS | J36: 250
A37: CD-134 | B37: Camión Plano | C37: International | D37: 4300 | E37: 2012 | F37: TALLER | G37: Sin asignar | H37: Operativo | I37: HORAS | J37: 250 | K37: 0
A38: CD-135 | B38: Camión Plano | C38: Mack | D38: GU 813 | E38: 2014 | F38: TALLER | G38: Sin asignar | H38: Fuera de Servicio | I38: HORAS | J38: 250
A39: CD-136 | B39: Camión Combustible | C39: Hino | D39: HZU | E39: 2015 | F39: TALLER | G39: Sin asignar | H39: Operativo | I39: HORAS | J39: 250 | K39: 81.79
A40: CD-137 | B40: Tracto Camión | C40: Mercedes Benz | D40: Axor 1936 | E40: 2014 | F40: Oficina Central | G40: Manuel Pacheco | H40: Operativo | I40: HORAS | J40: 250 | K40: 139.79
A41: CD-138 | B41: Camion Imprimador | C41: Sterling | D41: L7500 | F41: San Carlos | G41: Duban Rio | H41: Fuera de Servicio | I41: HORAS | J41: 250 | K41: 354.05
...

Sheet Lecturas
A1: LECTURAS (EDITABLE)
A3: Fecha | B3: Codigo | C3: Horometro | D3: Kilometraje | E3: Obra / Ubicacion | F3: Responsable | G3: Observacion
A4: 45992 | B4: CD-102 | C4: 9760 | D4: 243430
A5: 45992 | B5: CD-105 | C5: 10176 | D5: 242917
A6: 45992 | B6: CD-106 | C6: 8086 | D6: 160815
A7: 45992 | B7: CD-109 | D7: 185393
A8: 45992 | B8: CD-118 | D8: 499939
A9: 45992 | B9: CD-119
A10: 45992 | B10: CD-120 | C10: 3060 | D10: 73204
A11: 45992 | B11: CD-121 | C11: 3066 | D11: 78773
A12: 45992 | B12: CD-122 | C12: 3226
A13: 45992 | B13: CD-123 | C13: 3247 | D13: 91853
A14: 45992 | B14: CD-127 | D14: 110496
A15: 45992 | B15: CD-132 | C15: 7197 | D15: 180015
A16: 45992 | B16: CD-136 | D16: 55357
A17: 45992 | B17: CD-51 | D17: 801969
A18: 43886 | B18: MD-49 | C18: 14728
A19: 45992 | B19: CD-78 | D19: 292374
A20: 45992 | B20: CD-87 | C20: 9048 | D20: 191998
A21: 45992 | B21: CD-89 | C21: 8330 | D21: 160933
A22: 45992 | B22: CD-90 | C22: 8851 | D22: 200968
A23: 45992 | B23: CD-94 | C23: 8546 | D23: 161780
A24: 45992 | B24: EQP-11 | C24: 1825
A25: 45992 | B25: EQP-16 | C25: 6245
A26: 45992 | B26: EQP-18 | C26: 4667
A27: 45992 | B27: EQP-7 | C27: 15287
A28: 45992 | B28: MD-105 | C28: 687
A29: 45992 | B29: MD-107 | C29: 890
A30: 45992 | B30: MD-25 | C30: 14311
A31: 45992 | B31: MD-36
A32: 45992 | B32: MD-82 | C32: 10065
A33: 45992 | B33: MD-83 | C33: 7826
A34: 45992 | B34: MD-84 | C34: 5415
A35: 45992 | B35: MD-88 | C35: 6347
A36: 45992 | B36: MD-95 | C36: 1445
A37: 45992 | B37: MD-99 | C37: 1777
A38: 45992 | B38: VD-102 | D38: 84917
A39: 45992 | B39: VD-103 | D39: 66693
A40: 45992 | B40: VD-108 | D40: 66531
A41: 45992 | B41: VD-113 | D41: 102655
...

Sheet Mantenciones
A1: MANTENCIONES (EDITABLE)
A3: Fecha | B3: Codigo | C3: Tipo Mantencion | D3: Lectura | E3: EsPM | F3: Folio | G3: Lugar | H3: Proveedor | I3: Costo Mantencion CLP | J3: Estado
A4: 45967 | B4: MD-57 | C4: Mantencion 250Hrs | D4: 13469 | E4: Sí | F4: 15910 | J4: Finalizada
A5: 45954 | B5: MD-83 | C5: Mantencion 250Hrs | D5: 7636 | E5: Sí | F5: 15906 | J5: Finalizada
A6: 45967 | B6: MD-68 | C6: Mantencion 250Hrs | D6: 3240 | E6: Sí | F6: 15908 | J6: Finalizada
A7: 45994 | B7: MD-83 | C7: Tensar Correa Aire | D7: 7843 | E7: No | J7: Finalizada
A8: 46042 | B8: MD-83 | C8: Mantencion 250Hrs | D8: 8046 | E8: Sí | J8: Finalizada
A9: 46042 | B9: MD-89 | C9: C. Deslizaderas Balde | D9: 9878 | E9: No | J9: Finalizada
A10: 45972 | B10: CD-88 | C10: Mantencion 250Hrs | D10: 1453 | E10: Sí | F10: 15913 | J10: Finalizada
A11: 45980 | B11: CD-102 | C11: Mantencion 300Hr | D11: 9695 | E11: Sí | F11: 15914 | J11: Finalizada
A12: 45982 | B12: MD-95 | C12: Mantencion 300Hr | D12: 1413 | E12: Sí | F12: 15178 | J12: Finalizada
A13: 45985 | B13: MD-88 | C13: Mantencion 300Hr | D13: 6327 | E13: Sí | F13: 15179 | J13: Finalizada
A14: 45989 | B14: MD-64 | C14: R. Aceite 2.5Lt. | D14: 11688 | E14: No | F14: 15756 | J14: Finalizada
A15: 46042 | B15: MD-89 | C15: C. Aceite Hidr. 20Lt | D15: 9878 | E15: No | J15: Finalizada
A16: 45993 | B16: CD-122 | C16: Engrace Completo | D16: 85284 | E16: No | F16: 15761 | J16: Finalizada
A17: 45993 | B17: MD-102 | C17: Mantencion 300Hr | D17: 5321 | E17: Sí | F17: 15184 | J17: Finalizada
A18: 46043 | B18: MD-83 | C18: C. Balde Reforzado | D18: 8047 | E18: No | J18: Finalizada
A19: 45995 | B19: MD-94 | C19: Mantencion 300Hr | D19: 2060 | E19: Sí | F19: 15186 | J19: Finalizada
A20: 46008 | B20: VD-78 | C20: Mantencion 10mil | D20: 128090 | E20: Sí | F20: SN | J20: Finalizada
A21: 46009 | B21: VD-77 | C21: Mantencion * | D21: 128838 | E21: Sí | F21: SN | J21: Finalizada
A22: 46014 | B22: CD-97 | C22: Mantencion * | D22: 530211 | E22: Sí | F22: SN | J22: Finalizada
A23: 46015 | B23: CD-69 | C23: Mantencion 300Hr | D23: 461588 | E23: Sí | F23: 389 | J23: Finalizada
A24: 46028 | B24: MD-73 | C24: Mantencion * | D24: 17076 | E24: Sí | F24: 389 | J24: Finalizada
A25: 46028 | B25: CD-142 | C25: Mantencion * | D25: 331891 | E25: Sí | F25: 389 | J25: Finalizada
A26: 45971 | B26: MD-96 | C26: Mantencion * | D26: 1496 | E26: Sí | F26: 15912 | J26: Finalizada
A27: 46031 | B27: MD-109 | C27: Mantencion * | D27: 87661 | E27: Sí | F27: 389 | J27: Finalizada
A28: 46034 | B28: VD-119 | C28: Mantencion * | E28: Sí | F28: 389 | J28: Finalizada
A29: 46034 | B29: VD-84 | C29: Mantencion 10mil | D29: 118530 | E29: Sí | F29: SN | J29: Finalizada
A30: 46034 | B30: ED-73 | C30: Mantencion * | D30: 681 | E30: Sí | J30: Finalizada
A31: 45908 | B31: MD-107 | C31: Mantencion * | D31: 393 | E31: Sí | F31: 15911 | J31: Finalizada
A32: 46035 | B32: VD-91 | C32: Mantencion 10mil | D32: 105667 | E32: Sí | F32: 389 | J32: Finalizada
A33: 46036 | B33: VD-97 | C33: 138841 | D33: 99553 | E33: No | F33: 389 | J33: Finalizada
A34: 46036 | B34: VD-76 | C34: Mantencion 10mil | D34: 157018 | E34: Sí | F34: 389 | J34: Finalizada
A35: 46037 | B35: MD-25 | C35: R. Aceite Hidr. | E35: No | F35: 15429 | J35: Finalizada
A36: 46037 | B36: CD-109 | C36: Bateria | E36: No | F36: 15428 | J36: Finalizada
A37: 45967 | B37: MD-107 | C37: Mantencion * | D37: 748 | E37: Sí | F37: 15911 | J37: Finalizada
A38: 46037 | B38: VD-95 | C38: Mantencion 15000 | D38: 136208 | E38: Sí | F38: 389 | J38: Finalizada
A39: 45967 | B39: MD-100 | C39: Mantencion 300Hr | D39: 2000 | E39: Sí | F39: 15909 | J39: Finalizada
A40: 46041 | B40: CD-119 | C40: Engrace Completo | E40: No | J40: Finalizada
A41: 45992 | B41: MD-104 | E41: No | J41: Finalizada
...

Sheet Compras PM
A1: COMPRAS PM (EDITABLE)
A3: Fecha | B3: OC | C3: Codigo | D3: Descripcion | E3: Proveedor | F3: Costo PM CLP | G3: Regla | H3: Estado OC
A4: 46065.424 | B4: DEMO-02-7629 | C4: CD-69 | D4: FILTRO COMBUSTIBLE CD-69 | E4: DISTRIBUIDORA SOS FILTROS SpA | F4: 16422 | G4: Directo Equipo | H4: OC Cancelada
A5: 46065.519 | B5: DEMO-02-7633 | D5: SC-2-6076 KIT FILTROS PEUGEOT | E5: SOCIEDAD COMERCIAL SOCOFIL LIMITADA | F5: 322014 | G5: Preventivo sin equipo | H5: OC Aprobada
A6: 46069.442 | B6: DEMO-02-7642 | D6: SC-02-6084 KIT DE FILTROS MANTENCIO | E6: SOCIEDAD COMERCIAL SOCOFIL LIMITADA | F6: 21999.996 | G6: Prorrateo MAN | H6: OC Cancelada
A7: 46069.442 | B7: DEMO-02-7642 | C7: CD-103 | D7: SC-02-6084 KIT DE FILTROS MANTENCIO | E7: SOCIEDAD COMERCIAL SOCOFIL LIMITADA | F7: 21999.996 | G7: Prorrateo MAN | H7: OC Cancelada | W7: =IF(V7="FUERA DE SERVICIO","FUERA DE SERVICIO",IF(V7="SIN LECTURA / REVISAR","REVISAR 'Compras_PM'!C178LECTURA",IF(COUNTIFS(tblBodega[Codigo],A7)>0,"EN PROCESO",IF(OR(P7="",R7=""),"AL DÍA",IF(((J7+R7)-O7)<0,"ATRASADA",IF(((J7+R7)-O7)<=IF(K7=0,0,K7*7),"PRÓXIMA","AL DÍA")))))) -> AL DÍA
A8: 46069.442 | B8: DEMO-02-7642 | C8: CD-104 | D8: SC-02-6084 KIT DE FILTROS MANTENCIO | E8: SOCIEDAD COMERCIAL SOCOFIL LIMITADA | F8: 21999.996 | G8: Prorrateo MAN | H8: OC Cancelada
A9: 46069.442 | B9: DEMO-02-7642 | C9: CD-105 | D9: SC-02-6084 KIT DE FILTROS MANTENCIO | E9: SOCIEDAD COMERCIAL SOCOFIL LIMITADA | F9: 21999.996 | G9: Prorrateo MAN | H9: OC Cancelada
A10: 46069.442 | B10: DEMO-02-7642 | D10: SC-02-6084 KIT DE FILTROS MANTENCIO | E10: SOCIEDAD COMERCIAL SOCOFIL LIMITADA | F10: 21999.996 | G10: Prorrateo MAN | H10: OC Cancelada
A11: 46069.442 | B11: DEMO-02-7642 | C11: CD-107 | D11: SC-02-6084 KIT DE FILTROS MANTENCIO | E11: SOCIEDAD COMERCIAL SOCOFIL LIMITADA | F11: 21999.996 | G11: Prorrateo MAN | H11: OC Cancelada
A12: 46069.442 | B12: DEMO-02-7642 | C12: CD-120 | D12: SC-02-6084 KIT DE FILTROS MANTENCIO | E12: SOCIEDAD COMERCIAL SOCOFIL LIMITADA | F12: 21999.996 | G12: Prorrateo MAN | H12: OC Cancelada
A13: 46069.442 | B13: DEMO-02-7642 | C13: CD-121 | D13: SC-02-6084 KIT DE FILTROS MANTENCIO | E13: SOCIEDAD COMERCIAL SOCOFIL LIMITADA | F13: 21999.996 | G13: Prorrateo MAN | H13: OC Cancelada
A14: 46069.442 | B14: DEMO-02-7642 | C14: CD-122 | D14: SC-02-6084 KIT DE FILTROS MANTENCIO | E14: SOCIEDAD COMERCIAL SOCOFIL LIMITADA | F14: 21999.996 | G14: Prorrateo MAN | H14: OC Cancelada
A15: 46069.442 | B15: DEMO-02-7642 | C15: CD-123 | D15: SC-02-6084 KIT DE FILTROS MANTENCIO | E15: SOCIEDAD COMERCIAL SOCOFIL LIMITADA | F15: 21999.996 | G15: Prorrateo MAN | H15: OC Cancelada
A16: 46069.442 | B16: DEMO-02-7642 | C16: CD-124 | D16: SC-02-6084 KIT DE FILTROS MANTENCIO | E16: SOCIEDAD COMERCIAL SOCOFIL LIMITADA | F16: 21999.996 | G16: Prorrateo MAN | H16: OC Cancelada
A17: 46069.442 | B17: DEMO-02-7642 | C17: CD-87 | D17: SC-02-6084 KIT DE FILTROS MANTENCIO | E17: SOCIEDAD COMERCIAL SOCOFIL LIMITADA | F17: 21999.996 | G17: Prorrateo MAN | H17: OC Cancelada
A18: 46069.442 | B18: DEMO-02-7642 | C18: CD-88 | D18: SC-02-6084 KIT DE FILTROS MANTENCIO | E18: SOCIEDAD COMERCIAL SOCOFIL LIMITADA | F18: 21999.996 | G18: Prorrateo MAN | H18: OC Cancelada
A19: 46069.442 | B19: DEMO-02-7642 | C19: CD-89 | D19: SC-02-6084 KIT DE FILTROS MANTENCIO | E19: SOCIEDAD COMERCIAL SOCOFIL LIMITADA | F19: 21999.996 | G19: Prorrateo MAN | H19: OC Cancelada
A20: 46069.442 | B20: DEMO-02-7642 | C20: CD-90 | D20: SC-02-6084 KIT DE FILTROS MANTENCIO | E20: SOCIEDAD COMERCIAL SOCOFIL LIMITADA | F20: 21999.996 | G20: Prorrateo MAN | H20: OC Cancelada
A21: 46069.442 | B21: DEMO-02-7642 | C21: CD-91 | D21: SC-02-6084 KIT DE FILTROS MANTENCIO | E21: SOCIEDAD COMERCIAL SOCOFIL LIMITADA | F21: 21999.996 | G21: Prorrateo MAN | H21: OC Cancelada
A22: 46069.442 | B22: DEMO-02-7642 | C22: CD-94 | D22: SC-02-6084 KIT DE FILTROS MANTENCIO | E22: SOCIEDAD COMERCIAL SOCOFIL LIMITADA | F22: 21999.996 | G22: Prorrateo MAN | H22: OC Cancelada
A23: 46069.447 | B23: DEMO-02-7643 | D23: SC-02-6085 KIT DE FILTROS MANTENCIO | E23: SOCIEDAD COMERCIAL SOCOFIL LIMITADA | F23: 5764.6988 | G23: Prorrateo MAN | H23: OC Aprobada
A24: 46069.447 | B24: DEMO-02-7643 | C24: CD-103 | D24: SC-02-6085 KIT DE FILTROS MANTENCIO | E24: SOCIEDAD COMERCIAL SOCOFIL LIMITADA | F24: 5764.6988 | G24: Prorrateo MAN | H24: OC Aprobada
A25: 46069.447 | B25: DEMO-02-7643 | C25: CD-104 | D25: SC-02-6085 KIT DE FILTROS MANTENCIO | E25: SOCIEDAD COMERCIAL SOCOFIL LIMITADA | F25: 5764.6988 | G25: Prorrateo MAN | H25: OC Aprobada
A26: 46069.447 | B26: DEMO-02-7643 | C26: CD-105 | D26: SC-02-6085 KIT DE FILTROS MANTENCIO | E26: SOCIEDAD COMERCIAL SOCOFIL LIMITADA | F26: 5764.6988 | G26: Prorrateo MAN | H26: OC Aprobada
A27: 46069.447 | B27: DEMO-02-7643 | D27: SC-02-6085 KIT DE FILTROS MANTENCIO | E27: SOCIEDAD COMERCIAL SOCOFIL LIMITADA | F27: 5764.6988 | G27: Prorrateo MAN | H27: OC Aprobada
A28: 46069.447 | B28: DEMO-02-7643 | C28: CD-107 | D28: SC-02-6085 KIT DE FILTROS MANTENCIO | E28: SOCIEDAD COMERCIAL SOCOFIL LIMITADA | F28: 5764.6988 | G28: Prorrateo MAN | H28: OC Aprobada
A29: 46069.447 | B29: DEMO-02-7643 | C29: CD-120 | D29: SC-02-6085 KIT DE FILTROS MANTENCIO | E29: SOCIEDAD COMERCIAL SOCOFIL LIMITADA | F29: 5764.6988 | G29: Prorrateo MAN | H29: OC Aprobada
A30: 46069.447 | B30: DEMO-02-7643 | C30: CD-121 | D30: SC-02-6085 KIT DE FILTROS MANTENCIO | E30: SOCIEDAD COMERCIAL SOCOFIL LIMITADA | F30: 5764.6988 | G30: Prorrateo MAN | H30: OC Aprobada
A31: 46069.447 | B31: DEMO-02-7643 | C31: CD-122 | D31: SC-02-6085 KIT DE FILTROS MANTENCIO | E31: SOCIEDAD COMERCIAL SOCOFIL LIMITADA | F31: 5764.6988 | G31: Prorrateo MAN | H31: OC Aprobada
A32: 46069.447 | B32: DEMO-02-7643 | C32: CD-123 | D32: SC-02-6085 KIT DE FILTROS MANTENCIO | E32: SOCIEDAD COMERCIAL SOCOFIL LIMITADA | F32: 5764.6988 | G32: Prorrateo MAN | H32: OC Aprobada
A33: 46069.447 | B33: DEMO-02-7643 | C33: CD-124 | D33: SC-02-6085 KIT DE FILTROS MANTENCIO | E33: SOCIEDAD COMERCIAL SOCOFIL LIMITADA | F33: 5764.6988 | G33: Prorrateo MAN | H33: OC Aprobada
A34: 46069.447 | B34: DEMO-02-7643 | C34: CD-87 | D34: SC-02-6085 KIT DE FILTROS MANTENCIO | E34: SOCIEDAD COMERCIAL SOCOFIL LIMITADA | F34: 5764.6988 | G34: Prorrateo MAN | H34: OC Aprobada
A35: 46069.447 | B35: DEMO-02-7643 | C35: CD-88 | D35: SC-02-6085 KIT DE FILTROS MANTENCIO | E35: SOCIEDAD COMERCIAL SOCOFIL LIMITADA | F35: 5764.6988 | G35: Prorrateo MAN | H35: OC Aprobada
A36: 46069.447 | B36: DEMO-02-7643 | C36: CD-89 | D36: SC-02-6085 KIT DE FILTROS MANTENCIO | E36: SOCIEDAD COMERCIAL SOCOFIL LIMITADA | F36: 5764.6988 | G36: Prorrateo MAN | H36: OC Aprobada
A37: 46069.447 | B37: DEMO-02-7643 | C37: CD-90 | D37: SC-02-6085 KIT DE FILTROS MANTENCIO | E37: SOCIEDAD COMERCIAL SOCOFIL LIMITADA | F37: 5764.6988 | G37: Prorrateo MAN | H37: OC Aprobada
A38: 46069.447 | B38: DEMO-02-7643 | C38: CD-91 | D38: SC-02-6085 KIT DE FILTROS MANTENCIO | E38: SOCIEDAD COMERCIAL SOCOFIL LIMITADA | F38: 5764.6988 | G38: Prorrateo MAN | H38: OC Aprobada
A39: 46069.447 | B39: DEMO-02-7643 | C39: CD-94 | D39: SC-02-6085 KIT DE FILTROS MANTENCIO | E39: SOCIEDAD COMERCIAL SOCOFIL LIMITADA | F39: 5764.6988 | G39: Prorrateo MAN | H39: OC Aprobada
... A45: 46072.697 | B45: DEMO-02-7676 | C45: MD-84 | D45: SC-02-6093 KIT FILTROS MD-84 | E45: SALINAS Y FABRES | F45: 456581.58 | G45: Directo Equipo | H45: OC Enviada a Proveedor
A46: 46073.411 | B46: DEMO-02-7682 | D46: SC-02-FILTROS CAMIONES MAN (STOCK T | E46: AUTOMOTORA ALAMEDA SPA | F46: 13095.53 | G46: Prorrateo MAN | H46: OC Aprobada
...

Sheet Bodega
A1: BODEGA (EDITABLE)
A3: Folio | B3: Fecha | C3: Equipo | D3: Envio | E3: Persona que retiro | F3: Destino | G3: Comentario | H3: Codigo
A4: 18005 | B4: 46062 | C4: CD-115 | D4: Filtros Incompletos | E4: JC Celedon | F4: Taller | G4: Filtro Secador de Aire | H4: CD-115
A5: 18053 | B5: 46065 | C5: MD-68 | D5: Filtros Completos | E5: Osvaldo Faundez | F5: San Nicolas | H5: MD-68
A6: 18039 | B6: 46071 | C6: VD-112 | D6: Filtro Completros | E6: Luis Valenzuela | F6: Taller | H6: VD-112
A7: 18043 | B7: 46072 | C7: VD-120 | D7: Filtro Completros | E7: Daniel Andrade | F7: Taller | H7: VD-120
A8: 18093 | B8: 46072 | C8: VD-120 | D8: Filtros Completos | E8: Marcos Soto | F8: Taller | H8: VD-120
A9: 18093 | B9: 46072 | C9: VD-122 | D9: Filtros Completos | E9: Marcos Soto | F9: Taller | H9: VD-122
A10: 18206 | B10: 46073 | C10: VD-60 | D10: Filtro Completros | E10: Carlos Verdugo | F10: Q-61 | H10: VD-60
A11: 18207 | B11: 46073 | C11: MD-41 | D11: Filtro Completros | E11: Carlos Verdugo | F11: Q-61 | H11: MD-41
A12: 18208 | B12: 46073 | C12: MD-45 | D12: Filtros Incompletos | E12: Carlos Verdugo | F12: Q-61 | H12: MD-45
A13: 18049 | B13: 46073 | C13: VD-115 | D13: Filtro Completros | E13: Daniel Andrade | F13: Taller | H13: VD-115
A14: 18253 | B14: 46073 | C14: CD-69 | D14: Filtros Completros | E14: Daniel Andrade | F14: Taller | G14: Se cambiaron y se compraron de nuevo el kit de aire motor | H14: CD-69
A15: 18225 | B15: 46077 | C15: CD-87 | D15: Filtro Secador | E15: Carlos Verdugo | F15: Palmucho | H15: CD-87
A16: 18226 | B16: 46077 | C16: VD-29 | D16: Filtros Completos | E16: Manuel Ortiz | F16: Cobquecura | H16: VD-29
A17: 18230 | B17: 46077 | C17: MD-84 | D17: Filtros Completos | F17: Quirihue | H17: MD-84
A18: 18236 | B18: 46078 | C18: MD-55 | D18: Filtro Completros | E18: Bernardo Salinas | F18: Palmucho | H18: MD-55
A19: 18236 | B19: 46078 | C19: MD-67 | D19: Filtro Completros | E19: Bernardo Salinas | F19: Palmucho | H19: MD-67
A20: 18264 | B20: 46078 | C20: VD-118 | D20: Filtro Completros | E20: Daniel Andrade | F20: Taller | H20: VD-118
A21: 18246 | B21: 46079 | C21: MD-62 | D21: Filtro Completros | E21: Marcos Soto | F21: Curico | H21: MD-62
A22: 18302 | B22: 46080 | C22: CD-123 | D22: Filtros Completos | E22: Marcos Soto | F22: Quirihue | H22: CD-123
A23: 18304 | B23: 46080 | C23: CD-121 | D23: Filtros Completos | F23: Cobquecura | H23: CD-121
A24: 18304 | B24: 46080 | C24: CD-120 | D24: Filtros Completos | F24: Cobquecura | H24: CD-120
A25: 18305 | B25: 46080 | C25: MD-94 | D25: Filtros Completos | F25: Cobquecura | H25: MD-94
A26: 18306 | B26: 46080 | C26: CD-140 | D26: Filtros Completos | F26: Cobquecura | H26: CD-140
A27: 18307 | B27: 46080 | C27: MD-26 | D27: Filtros Completos | F27: Cobquecura | H27: MD-26
A28: 18308 | B28: 46080 | C28: MD-95 | D28: Filtros Incompletos | F28: Quirihue | G28: Filtro decantador / Filtro Combustible / Filtro Aceite | H28: MD-95
A29: 18310 | B29: 46080 | C29: VD-124 | D29: Filtros Completos | F29: Cobquecura | H29: VD-124
A30: 18276 | B30: 46080 | C30: CD-125 | D30: Filtros Incompletos | E30: Patricio Novoa | G30: Filtro de combustible / Filtro de Aceite | H30: CD-125
A31: 18280 | B31: 46083 | C31: MD-51 | D31: Filtro Completros | F31: Palmucho | H31: MD-51
A32: 18284 | B32: 46083 | C32: MD-96 | D32: Filtros Completos | E32: Juan Roco | F32: San Carlos | H32: MD-96
A33: 18288 | B33: 46083 | C33: MD-94 | D33: Filtro Completros | F33: Palmucho | H33: MD-94
A34: 18289 | B34: 46083 | C34: MD-98 | D34: Filtros Completros | E34: Roberto Ventura | F34: Q-61 | H34: MD-98
A35: 18322 | B35: 46084 | C35: CD-107 | D35: Filtros Incompletos | E35: Daniel Andrade | F35: Taller | G35: Filtro decantador / Filtro Combustible | H35: CD-107
A36: 18332 | B36: 46085 | C36: CD-86 | D36: Filtros Completos | E36: Marcos Soto | F36: Quirihue | H36: CD-86
A37: 18332 | B37: 46085 | C37: VD-113 | D37: Filtros Completos | E37: Marcos Soto | F37: Quirihue | H37: VD-113
A38: 18337 | B38: 46085 | C38: MD-39 | D38: Filtro Completros | E38: Alejandro Poblete | F38: Colbun | H38: MD-39
A39: 18341 | B39: 46085 | C39: MD-25 | D39: Filtros Completos | F39: San Carlos | H39: MD-25
A40: 18360 | B40: 46087 | C40: MD-25 | D40: Aceite 15w40 | E40: Alejandro Poblete | F40: San Carlos | H40: MD-25
A41: 18360 | B41: 46087 | C41: VD-121 | D41: Filtros Completos | E41: Alejandro Poblete | F41: San Carlos | H41: VD-121
...

Sheet Maestro_Equipos
A1: Maestro de Equipos
A3: Codigo | B3: Tipo Equipo | C3: Familia | D3: Marca | E3: Modelo | F3: Año | G3: Ubicacion | H3: Responsable | I3: Control Base | J3: Frecuencia Base | K3: Promedio Diario | L3: Ultima Fecha Lectura | M3: Ultimo Horometro | N3: Ultimo Kilometraje | O3: Lectura Actual | P3: Ultima Fecha PM | Q3: Ultima PM | R3: Ultima Lectura PM | S3: Costo Mantenciones CLP | T3: Costo Compras PM CLP | U3: Costo Total PM CLP | V3: Estado Operacional | W3: Estado CMMS | X3: Dias a Proxima Mantencion | Y3: Fecha Est. Proxima Mantencion | Z3: Fecha Compra PM | AA3: Fecha Salida Bodega | AB3: Tiempo Compra → Mantención | AC3: Tiempo Bodega → Mantención | AD3: Estado Bodega → Mantención | AE3: Estado Operativo Real | AF3: Prioridad Taller | AG3: Acción Sugerida | AH3: _CompraRequerida | AI3: _OrdenCompra | AJ3: Criticidad
A4: CD-69 | B4: Tracto Camión | C4: Camiones de Ruta | D4: Scania | E4: P400A | F4: 2018 | G4: {=IFERROR(INDEX(Lecturas!$E$4:$E$3549,MATCH(1,(Lecturas!$B$4:$B$3549=$A4)*(Lecturas!$E$4:$E$3549<>"")*(Lecturas!$A$4:$A$3549=_xlfn.MAXIFS(Lecturas!$A$4:$A$3549,Lecturas!$B$4:$B$3549,$A4,Lecturas!$E$4:$E$3549,"<>")),0)),"")} | H4: Pedro Rojas | I4: HORAS | J4: 250 | K4: =IFERROR(IF($I4="KM",ROUND((_xlfn.MAXIFS(tblLecturas[Kilometraje],tblLecturas[Codigo],$A4)-_xlfn.MINIFS(tblLecturas[Kilometraje],tblLecturas[Codigo],$A4))/(MAX(1,_xlfn.MAXIFS(tblLecturas[Fecha],tblLecturas[Codigo],$A4)-_xlfn.MINIFS(tblLecturas[Fecha],tblLecturas[Codigo],$A4))),1),ROUND((_xlfn.MAXIFS(tblLecturas[Horometro],tblLecturas[Codigo],$A4)-_xlfn.MINIFS(tblLecturas[Horometro],tblLecturas[Codigo],$A4))/(MAX(1,_xlfn.MAXIFS(tblLecturas[Fecha],tblLecturas[Codigo],$A4)-_xlfn.MINIFS(tblLecturas[Fecha],tblLecturas[Codigo],$A4))),1)),"") -> 0.6 | L4: =IFERROR(_xlfn.MAXIFS(tblLecturas[Fecha],tblLecturas[Codigo],$A4),"") -> 46107 | M4: =IFERROR(_xlfn.MAXIFS(Lecturas!$C:$C,Lecturas!$B:$B,$A4,Lecturas!$C:$C,">0"),"") -> 8002 | N4: =IFERROR(_xlfn.MAXIFS(tblLecturas[Kilometraje],tblLecturas[Codigo],$A4,tblLecturas[Kilometraje],">0"),"") -> 775645 | O4: {=IFERROR(IF($I4="KM",LOOKUP(2,1/(Lecturas!$B:$B=$A4)/(Lecturas!$D:$D>0),Lecturas!$D:$D),LOOKUP(2,1/(Lecturas!$B:$B=$A4)/(Lecturas!$C:$C>0),Lecturas!$C:$C)),"")} -> 8002 | P4: =IFERROR(_xlfn.MAXIFS(tblMantenciones[Fecha],tblMantenciones[Codigo],tblMaestroEquipos[[#This Row],[Codigo]],tblMantenciones[EsPM],"Sí"),"") -> 46073 | Q4: =IF(_xlfn.MAXIFS(Mantenciones!$D:$D,Mantenciones!$B:$B,A4)=0,"Sin datos de mantención registrado",_xlfn.MAXIFS(Mantenciones!$D:$D,Mantenciones!$B:$B,A4)) -> 461588 | R4: =IFERROR(IF(_xlfn.MAXIFS(Mantenciones!$D:$D,Mantenciones!$B:$B,$A4,Mantenciones!$E:$E,"Sí",Mantenciones!$D:$D,">0")=0,"Sin datos de mantención registrado",_xlfn.MAXIFS(Mantenciones!$D:$D,Mantenciones!$B:$B,$A4,Mantenciones!$E:$E,"Sí",Mantenciones!$D:$D,">0")),"Sin datos de mantención registrado") -> 461588 | S4: =IFERROR(SUMIFS(tblMantenciones[Costo Mantencion CLP],tblMantenciones[Codigo],A4),0) -> 0 | T4: =IFERROR(SUMIFS(tblComprasPM[Costo PM CLP],tblComprasPM[Codigo],tblMaestroEquipos[[#This Row],[Codigo]]),0) -> 255115.17 | U4: =IFERROR(tblMaestroEquipos[[#This Row],[Costo Mantenciones CLP]]+tblMaestroEquipos[[#This Row],[Costo Compras PM CLP]],0) -> 255115.17 | V4: =IFERROR(_xlfn.XLOOKUP(tblMaestroEquipos[[#This Row],[Codigo]],tblEquipos[Codigo],tblEquipos[Estado Base]),"") -> Operativo | W4: =IF(OR(TRIM($V4)="Fuera de Servicio",TRIM($V4)="Fuera de servicio"),"FUERA DE SERVICIO",IF(OR(TRIM($V4)="Taller",TRIM($V4)="En taller",TRIM($V4)="EN TALLER"),"EN TALLER",IF($AD4="PENDIENTE","POR RECIBIR",IF(AND($Z4<>"",$AA4=""),"EN PROCESO",IF(AND(ISNUMBER($X4),$X4<0),"ATRASADA",IF(AND(ISNUMBER($X4),$X4<=30),"PRÓXIMA","AL DÍA")))))) -> AL DÍA | X4: =IF(OR(NOT(ISNUMBER(R4)),NOT(ISNUMBER(J4)),NOT(ISNUMBER(O4))),"", (R4+J4)-O4) -> 453836 | Y4: =IFERROR(IF($X4="","",TODAY()+$X4),"") -> 499981 | Z4: =IFERROR(IF(_xlfn.MINIFS(tblComprasPM[Fecha],tblComprasPM[Codigo],tblMaestroEquipos[[#This Row],[Codigo]])=0,"",_xlfn.MINIFS(tblComprasPM[Fecha],tblComprasPM[Codigo],tblMaestroEquipos[[#This Row],[Codigo]])),"") -> 46065.424 | AA4: =IFERROR(IF(_xlfn.MAXIFS(tblBodega[Fecha],tblBodega[Codigo],tblMaestroEquipos[[#This Row],[Codigo]])=0,"",_xlfn.MAXIFS(tblBodega[Fecha],tblBodega[Codigo],tblMaestroEquipos[[#This Row],[Codigo]])),"") -> 46073 | AB4: =IFERROR(IF(OR(tblMaestroEquipos[[#This Row],[Fecha Compra PM]]="",tblMaestroEquipos[[#This Row],[Fecha Compra PM]]=0),"",IF(OR(tblMaestroEquipos[[#This Row],[Ultima Fecha PM]]="",tblMaestroEquipos[[#This Row],[Ultima Fecha PM]]=0),MAX(0,INT(TODAY())-INT(tblMaestroEquipos[[#This Row],[Fecha Compra PM]])),MAX(0,INT(tblMaestroEquipos[[#This Row],[Ultima Fecha PM]])-INT(tblMaestroEquipos[[#This Row],[Fecha Compra PM]])))),"") -> 8 | AC4: =IFERROR(IF(OR(tblMaestroEquipos[[#This Row],[Fecha Salida Bodega]]="",tblMaestroEquipos[[#This Row],[Fecha Salida Bodega]]=0),"",IF(OR(tblMaestroEquipos[[#This Row],[Ultima Fecha PM]]="",tblMaestroEquipos[[#This Row],[Ultima Fecha PM]]=0),MAX(0,INT(TODAY())-INT(tblMaestroEquipos[[#This Row],[Fecha Salida Bodega]])),MAX(0,INT(tblMaestroEquipos[[#This Row],[Ultima Fecha PM]])-INT(tblMaestroEquipos[[#This Row],[Fecha Salida Bodega]])))),"") -> 0 | AD4: =IF(tblMaestroEquipos[[#This Row],[Fecha Salida Bodega]]="","SIN SALIDA BODEGA",IF(OR(tblMaestroEquipos[[#This Row],[Ultima Fecha PM]]="",tblMaestroEquipos[[#This Row],[Ultima Fecha PM]]<tblMaestroEquipos[[#This Row],[Fecha Salida Bodega]]),"PENDIENTE","CERRADO")) -> CERRADO | AE4: =IF(TRIM(V4)="Fuera de servicio","FUERA DE SERVICIO", IF(OR(TRIM(V4)="Taller",TRIM(V4)="En taller"),"EN TALLER", IF(W4="ATRASADO","ATRASADO", IF(W4="EN PROCESO","EN PROCESO", IF(W4="PRÓXIMO","PRÓXIMO", "OPERATIVO"))))) -> OPERATIVO | AF4: =IF($AE4="ATRASADA",IF($X4<=-15,"CRÍTICA","ALTA"),IF($AE4="PRÓXIMA","MEDIA",IF(OR($AE4="EN PROCESO",$AE4="POR RECIBIR"),"SEGUIMIENTO",IF($AE4="FUERA DE SERVICIO","NO APLICA","BAJA")))) -> BAJA | AG4: =IF($AE4="FUERA DE SERVICIO","No programar compra",IF($AE4="CERRADO","Cerrar ciclo y preparar siguiente PM",IF($AE4="EN PROCESO","Hacer seguimiento al taller y cerrar report",IF($AE4="POR RECIBIR","Acelerar recepción de repuestos",IF($AE4="ATRASADA","Comprar kit PM y coordinar ejecución",IF($AE4="PRÓXIMA","Planificar compra preventiva","Monitorear próximo vencimiento")))))) -> Monitorear próximo vencimiento | AH4: =IF(AND(OR($AE4="ATRASADA",$AE4="PRÓXIMA"),$Z4="",$AA4=""),1,0) -> 0 | AI4: =IF(OR($AH4=0,$Y4=""),"",SUMPRODUCT(($AH$4:$AH$247=1)*(($Y$4:$Y$247<$Y4)+(($Y$4:$Y$247=$Y4)*(ROW($Y$4:$Y$247)<=ROW()))))) | AJ4: =IF(W4="ATRASADA",1,IF(W4="EN PROCESO",2,IF(W4="POR RECIBIR",3,99))) -> 99
A5: CD-118 | B5: Camión Plano | C5: Camiones de Ruta | D5: Freightliner | E5: M2 106 | F5: 2010 | G5: {=IFERROR(INDEX(Lecturas!$E$4:$E$3549,MATCH(1,(Lecturas!$B$4:$B$3549=$A5)*(Lecturas!$E$4:$E$3549<>"")*(Lecturas!$A$4:$A$3549=_xlfn.MAXIFS(Lecturas!$A$4:$A$3549,Lecturas!$B$4:$B$3549,$A5,Lecturas!$E$4:$E$3549,"<>")),0)),"")} -> Quirihue | H5: Carlos Vasquez | I5: HORAS | J5: 250 | K5: =IFERROR(IF($I5="KM",ROUND((_xlfn.MAXIFS(tblLecturas[Kilometraje],tblLecturas[Codigo],$A5)-_xlfn.MINIFS(tblLecturas[Kilometraje],tblLecturas[Codigo],$A5))/(MAX(1,_xlfn.MAXIFS(tblLecturas[Fecha],tblLecturas[Codigo],$A5)-_xlfn.MINIFS(tblLecturas[Fecha],tblLecturas[Codigo],$A5))),1),ROUND((_xlfn.MAXIFS(tblLecturas[Horometro],tblLecturas[Codigo],$A5)-_xlfn.MINIFS(tblLecturas[Horometro],tblLecturas[Codigo],$A5))/(MAX(1,_xlfn.MAXIFS(tblLecturas[Fecha],tblLecturas[Codigo],$A5)-_xlfn.MINIFS(tblLecturas[Fecha],tblLecturas[Codigo],$A5))),1)),"") -> 0 | L5: =IFERROR(_xlfn.MAXIFS(tblLecturas[Fecha],tblLecturas[Codigo],$A5),"") -> 46099 | M5: =IFERROR(_xlfn.MAXIFS(Lecturas!$C:$C,Lecturas!$B:$B,$A5,Lecturas!$C:$C,">0"),"") -> 0 | N5: =IFERROR(_xlfn.MAXIFS(tblLecturas[Kilometraje],tblLecturas[Codigo],$A5,tblLecturas[Kilometraje],">0"),"") -> 917261 | O5: {=IFERROR(IF($I5="KM",LOOKUP(2,1/(Lecturas!$B:$B=$A5)/(Lecturas!$D:$D>0),Lecturas!$D:$D),LOOKUP(2,1/(Lecturas!$B:$B=$A5)/(Lecturas!$C:$C>0),Lecturas!$C:$C)),"")} | P5: =IFERROR(_xlfn.MAXIFS(tblMantenciones[Fecha],tblMantenciones[Codigo],tblMaestroEquipos[[#This Row],[Codigo]],tblMantenciones[EsPM],"Sí"),"") -> 0 | Q5: =IF(_xlfn.MAXIFS(Mantenciones!$D:$D,Mantenciones!$B:$B,A5)=0,"Sin datos de mantención registrado",_xlfn.MAXIFS(Mantenciones!$D:$D,Mantenciones!$B:$B,A5)) -> Sin datos de mantención registrado | R5: =IFERROR(IF(_xlfn.MAXIFS(Mantenciones!$D:$D,Mantenciones!$B:$B,$A5,Mantenciones!$E:$E,"Sí",Mantenciones!$D:$D,">0")=0,"Sin datos de mantención registrado",_xlfn.MAXIFS(Mantenciones!$D:$D,Mantenciones!$B:$B,$A5,Mantenciones!$E:$E,"Sí",Mantenciones!$D:$D,">0")),"Sin datos de mantención registrado") -> Sin datos de mantención registrado | S5: =IFERROR(SUMIFS(tblMantenciones[Costo Mantencion CLP],tblMantenciones[Codigo],A5),0) -> 0 | T5: =IFERROR(SUMIFS(tblComprasPM[Costo PM CLP],tblComprasPM[Codigo],tblMaestroEquipos[[#This Row],[Codigo]]),0) -> 0 | U5: =IFERROR(tblMaestroEquipos[[#This Row],[Costo Mantenciones CLP]]+tblMaestroEquipos[[#This Row],[Costo Compras PM CLP]],0) -> 0 | V5: =IFERROR(_xlfn.XLOOKUP(tblMaestroEquipos[[#This Row],[Codigo]],tblEquipos[Codigo],tblEquipos[Estado Base]),"") -> Operativo | W5: =IF(OR(TRIM($V5)="Fuera de Servicio",TRIM($V5)="Fuera de servicio"),"FUERA DE SERVICIO",IF(OR(TRIM($V5)="Taller",TRIM($V5)="En taller",TRIM($V5)="EN TALLER"),"EN TALLER",IF($AD5="PENDIENTE","POR RECIBIR",IF(AND($Z5<>"",$AA5=""),"EN PROCESO",IF(AND(ISNUMBER($X5),$X5<0),"ATRASADA",IF(AND(ISNUMBER($X5),$X5<=30),"PRÓXIMA","AL DÍA")))))) -> AL DÍA | X5: =IF(OR(NOT(ISNUMBER(R5)),NOT(ISNUMBER(J5)),NOT(ISNUMBER(O5))),"", (R5+J5)-O5) | Y5: =IFERROR(IF($X5="","",TODAY()+$X5),"") | Z5: =IFERROR(IF(_xlfn.MINIFS(tblComprasPM[Fecha],tblComprasPM[Codigo],tblMaestroEquipos[[#This Row],[Codigo]])=0,"",_xlfn.MINIFS(tblComprasPM[Fecha],tblComprasPM[Codigo],tblMaestroEquipos[[#This Row],[Codigo]])),"") | AA5: =IFERROR(IF(_xlfn.MAXIFS(tblBodega[Fecha],tblBodega[Codigo],tblMaestroEquipos[[#This Row],[Codigo]])=0,"",_xlfn.MAXIFS(tblBodega[Fecha],tblBodega[Codigo],tblMaestroEquipos[[#This Row],[Codigo]])),"") | AB5: =IFERROR(IF(OR(tblMaestroEquipos[[#This Row],[Fecha Compra PM]]="",tblMaestroEquipos[[#This Row],[Fecha Compra PM]]=0),"",IF(OR(tblMaestroEquipos[[#This Row],[Ultima Fecha PM]]="",tblMaestroEquipos[[#This Row],[Ultima Fecha PM]]=0),MAX(0,INT(TODAY())-INT(tblMaestroEquipos[[#This Row],[Fecha Compra PM]])),MAX(0,INT(tblMaestroEquipos[[#This Row],[Ultima Fecha PM]])-INT(tblMaestroEquipos[[#This Row],[Fecha Compra PM]])))),"") | AC5: =IFERROR(IF(OR(tblMaestroEquipos[[#This Row],[Fecha Salida Bodega]]="",tblMaestroEquipos[[#This Row],[Fecha Salida Bodega]]=0),"",IF(OR(tblMaestroEquipos[[#This Row],[Ultima Fecha PM]]="",tblMaestroEquipos[[#This Row],[Ultima Fecha PM]]=0),MAX(0,INT(TODAY())-INT(tblMaestroEquipos[[#This Row],[Fecha Salida Bodega]])),MAX(0,INT(tblMaestroEquipos[[#This Row],[Ultima Fecha PM]])-INT(tblMaestroEquipos[[#This Row],[Fecha Salida Bodega]])))),"") | AD5: =IF(tblMaestroEquipos[[#This Row],[Fecha Salida Bodega]]="","SIN SALIDA BODEGA",IF(OR(tblMaestroEquipos[[#This Row],[Ultima Fecha PM]]="",tblMaestroEquipos[[#This Row],[Ultima Fecha PM]]<tblMaestroEquipos[[#This Row],[Fecha Salida Bodega]]),"PENDIENTE","CERRADO")) -> SIN SALIDA BODEGA | AE5: =IF(TRIM(V5)="Fuera de servicio","FUERA DE SERVICIO", IF(OR(TRIM(V5)="Taller",TRIM(V5)="En taller"),"EN TALLER", IF(W5="ATRASADO","ATRASADO", IF(W5="EN PROCESO","EN PROCESO", IF(W5="PRÓXIMO","PRÓXIMO", "OPERATIVO"))))) -> OPERATIVO | AF5: =IF($AE5="ATRASADA",IF($X5<=-15,"CRÍTICA","ALTA"),IF($AE5="PRÓXIMA","MEDIA",IF(OR($AE5="EN PROCESO",$AE5="POR RECIBIR"),"SEGUIMIENTO",IF($AE5="FUERA DE SERVICIO","NO APLICA","BAJA")))) -> BAJA | AG5: =IF($AE5="FUERA DE SERVICIO","No programar compra",IF($AE5="CERRADO","Cerrar ciclo y preparar siguiente PM",IF($AE5="EN PROCESO","Hacer seguimiento al taller y cerrar report",IF($AE5="POR RECIBIR","Acelerar recepción de repuestos",IF($AE5="ATRASADA","Comprar kit PM y coordinar ejecución",IF($AE5="PRÓXIMA","Planificar compra preventiva","Monitorear próximo vencimiento")))))) -> Monitorear próximo vencimiento | AH5: =IF(AND(OR($AE5="ATRASADA",$AE5="PRÓXIMA"),$Z5="",$AA5=""),1,0) -> 0 | AI5: =IF(OR($AH5=0,$Y5=""),"",SUMPRODUCT(($AH$4:$AH$247=1)*(($Y$4:$Y$247<$Y5)+(($Y$4:$Y$247=$Y5)*(ROW($Y$4:$Y$247)<=ROW()))))) | AJ5: =IF(W5="ATRASADA",1,IF(W5="EN PROCESO",2,IF(W5="POR RECIBIR",3,99))) -> 99
A6: CD-127 | B6: Camión Pluma | C6: Camiones de Ruta | D6: International | E6: 4300 | F6: 2012 | G6: {=IFERROR(INDEX(Lecturas!$E$4:$E$3549,MATCH(1,(Lecturas!$B$4:$B$3549=$A6)*(Lecturas!$E$4:$E$3549<>"")*(Lecturas!$A$4:$A$3549=_xlfn.MAXIFS(Lecturas!$A$4:$A$3549,Lecturas!$B$4:$B$3549,$A6,Lecturas!$E$4:$E$3549,"<>")),0)),"")} -> Oficina Central | H6: Sin asignar | I6: HORAS | J6: 250 | K6: =IFERROR(IF($I6="KM",ROUND((_xlfn.MAXIFS(tblLecturas[Kilometraje],tblLecturas[Codigo],$A6)-_xlfn.MINIFS(tblLecturas[Kilometraje],tblLecturas[Codigo],$A6))/(MAX(1,_xlfn.MAXIFS(tblLecturas[Fecha],tblLecturas[Codigo],$A6)-_xlfn.MINIFS(tblLecturas[Fecha],tblLecturas[Codigo],$A6))),1),ROUND((_xlfn.MAXIFS(tblLecturas[Horometro],tblLecturas[Codigo],$A6)-_xlfn.MINIFS(tblLecturas[Horometro],tblLecturas[Codigo],$A6))/(MAX(1,_xlfn.MAXIFS(tblLecturas[Fecha],tblLecturas[Codigo],$A6)-_xlfn.MINIFS(tblLecturas[Fecha],tblLecturas[Codigo],$A6))),1)),"") -> 0 | L6: =IFERROR(_xlfn.MAXIFS(tblLecturas[Fecha],tblLecturas[Codigo],$A6),"") -> 46114 | M6: =IFERROR(_xlfn.MAXIFS(Lecturas!$C:$C,Lecturas!$B:$B,$A6,Lecturas!$C:$C,">0"),"") -> 0 | N6: =IFERROR(_xlfn.MAXIFS(tblLecturas[Kilometraje],tblLecturas[Codigo],$A6,tblLecturas[Kilometraje],">0"),"") -> 511388 | O6: {=IFERROR(IF($I6="KM",LOOKUP(2,1/(Lecturas!$B:$B=$A6)/(Lecturas!$D:$D>0),Lecturas!$D:$D),LOOKUP(2,1/(Lecturas!$B:$B=$A6)/(Lecturas!$C:$C>0),Lecturas!$C:$C)),"")} | P6: =IFERROR(_xlfn.MAXIFS(tblMantenciones[Fecha],tblMantenciones[Codigo],tblMaestroEquipos[[#This Row],[Codigo]],tblMantenciones[EsPM],"Sí"),"") -> 46129 | Q6: =IF(_xlfn.MAXIFS(Mantenciones!$D:$D,Mantenciones!$B:$B,A6)=0,"Sin datos de mantención registrado",_xlfn.MAXIFS(Mantenciones!$D:$D,Mantenciones!$B:$B,A6)) -> 138500 | R6: =IFERROR(IF(_xlfn.MAXIFS(Mantenciones!$D:$D,Mantenciones!$B:$B,$A6,Mantenciones!$E:$E,"Sí",Mantenciones!$D:$D,">0")=0,"Sin datos de mantención registrado",_xlfn.MAXIFS(Mantenciones!$D:$D,Mantenciones!$B:$B,$A6,Mantenciones!$E:$E,"Sí",Mantenciones!$D:$D,">0")),"Sin datos de mantención registrado") -> 138500 | S6: =IFERROR(SUMIFS(tblMantenciones[Costo Mantencion CLP],tblMantenciones[Codigo],A6),0) -> 0 | T6: =IFERROR(SUMIFS(tblComprasPM[Costo PM CLP],tblComprasPM[Codigo],tblMaestroEquipos[[#This Row],[Codigo]]),0) -> 222792.99 | U6: =IFERROR(tblMaestroEquipos[[#This Row],[Costo Mantenciones CLP]]+tblMaestroEquipos[[#This Row],[Costo Compras PM CLP]],0) -> 222792.99 | V6: =IFERROR(_xlfn.XLOOKUP(tblMaestroEquipos[[#This Row],[Codigo]],tblEquipos[Codigo],tblEquipos[Estado Base]),"") -> Operativo | W6: =IF(OR(TRIM($V6)="Fuera de Servicio",TRIM($V6)="Fuera de servicio"),"FUERA DE SERVICIO",IF(OR(TRIM($V6)="Taller",TRIM($V6)="En taller",TRIM($V6)="EN TALLER"),"EN TALLER",IF($AD6="PENDIENTE","POR RECIBIR",IF(AND($Z6<>"",$AA6=""),"EN PROCESO",IF(AND(ISNUMBER($X6),$X6<0),"ATRASADA",IF(AND(ISNUMBER($X6),$X6<=30),"PRÓXIMA","AL DÍA")))))) -> AL DÍA | X6: =IF(OR(NOT(ISNUMBER(R6)),NOT(ISNUMBER(J6)),NOT(ISNUMBER(O6))),"", (R6+J6)-O6) | Y6: =IFERROR(IF($X6="","",TODAY()+$X6),"") | Z6: =IFERROR(IF(_xlfn.MINIFS(tblComprasPM[Fecha],tblComprasPM[Codigo],tblMaestroEquipos[[#This Row],[Codigo]])=0,"",_xlfn.MINIFS(tblComprasPM[Fecha],tblComprasPM[Codigo],tblMaestroEquipos[[#This Row],[Codigo]])),"") -> 46086.706 | AA6: =IFERROR(IF(_xlfn.MAXIFS(tblBodega[Fecha],tblBodega[Codigo],tblMaestroEquipos[[#This Row],[Codigo]])=0,"",_xlfn.MAXIFS(tblBodega[Fecha],tblBodega[Codigo],tblMaestroEquipos[[#This Row],[Codigo]])),"") -> 46129 | AB6: =IFERROR(IF(OR(tblMaestroEquipos[[#This Row],[Fecha Compra PM]]="",tblMaestroEquipos[[#This Row],[Fecha Compra PM]]=0),"",IF(OR(tblMaestroEquipos[[#This Row],[Ultima Fecha PM]]="",tblMaestroEquipos[[#This Row],[Ultima Fecha PM]]=0),MAX(0,INT(TODAY())-INT(tblMaestroEquipos[[#This Row],[Fecha Compra PM]])),MAX(0,INT(tblMaestroEquipos[[#This Row],[Ultima Fecha PM]])-INT(tblMaestroEquipos[[#This Row],[Fecha Compra PM]])))),"") -> 43 | AC6: =IFERROR(IF(OR(tblMaestroEquipos[[#This Row],[Fecha Salida Bodega]]="",tblMaestroEquipos[[#This Row],[Fecha Salida Bodega]]=0),"",IF(OR(tblMaestroEquipos[[#This Row],[Ultima Fecha PM]]="",tblMaestroEquipos[[#This Row],[Ultima Fecha PM]]=0),MAX(0,INT(TODAY())-INT(tblMaestroEquipos[[#This Row],[Fecha Salida Bodega]])),MAX(0,INT(tblMaestroEquipos[[#This Row],[Ultima Fecha PM]])-INT(tblMaestroEquipos[[#This Row],[Fecha Salida Bodega]])))),"") -> 0 | AD6: =IF(tblMaestroEquipos[[#This Row],[Fecha Salida Bodega]]="","SIN SALIDA BODEGA",IF(OR(tblMaestroEquipos[[#This Row],[Ultima Fecha PM]]="",tblMaestroEquipos[[#This Row],[Ultima Fecha PM]]<tblMaestroEquipos[[#This Row],[Fecha Salida Bodega]]),"PENDIENTE","CERRADO")) -> CERRADO | AE6: =IF(TRIM(V6)="Fuera de servicio","FUERA DE SERVICIO", IF(OR(TRIM(V6)="Taller",TRIM(V6)="En taller"),"EN TALLER", IF(W6="ATRASADO","ATRASADO", IF(W6="EN PROCESO","EN PROCESO", IF(W6="PRÓXIMO","PRÓXIMO", "OPERATIVO"))))) -> OPERATIVO | AF6: =IF($AE6="ATRASADA",IF($X6<=-15,"CRÍTICA","ALTA"),IF($AE6="PRÓXIMA","MEDIA",IF(OR($AE6="EN PROCESO",$AE6="POR RECIBIR"),"SEGUIMIENTO",IF($AE6="FUERA DE SERVICIO","NO APLICA","BAJA")))) -> BAJA | AG6: =IF($AE6="FUERA DE SERVICIO","No programar compra",IF($AE6="CERRADO","Cerrar ciclo y preparar siguiente PM",IF($AE6="EN PROCESO","Hacer seguimiento al taller y cerrar report",IF($AE6="POR RECIBIR","Acelerar recepción de repuestos",IF($AE6="ATRASADA","Comprar kit PM y coordinar ejecución",IF($AE6="PRÓXIMA","Planificar compra preventiva","Monitorear próximo vencimiento")))))) -> Monitorear próximo vencimiento | AH6: =IF(AND(OR($AE6="ATRASADA",$AE6="PRÓXIMA"),$Z6="",$AA6=""),1,0) -> 0 | AI6: =IF(OR($AH6=0,$Y6=""),"",SUMPRODUCT(($AH$4:$AH$247=1)*(($Y$4:$Y$247<$Y6)+(($Y$4:$Y$247=$Y6)*(ROW($Y$4:$Y$247)<=ROW()))))) | AJ6: =IF(W6="ATRASADA",1,IF(W6="EN PROCESO",2,IF(W6="POR RECIBIR",3,99))) -> 99
A7: CD-128 | B7: Camión slurry | C7: Camiones de Ruta | D7: Mack | E7: GU 813 | F7: 2012 | G7: {=IFERROR(INDEX(Lecturas!$E$4:$E$3549,MATCH(1,(Lecturas!$B$4:$B$3549=$A7)*(Lecturas!$E$4:$E$3549<>"")*(Lecturas!$A$4:$A$3549=_xlfn.MAXIFS(Lecturas!$A$4:$A$3549,Lecturas!$B$4:$B$3549,$A7,Lecturas!$E$4:$E$3549,"<>")),0)),"")} -> Palmucho | H7: Sin asignar | I7: HORAS | J7: 250 | K7: =IFERROR(IF($I7="KM",ROUND((_xlfn.MAXIFS(tblLecturas[Kilometraje],tblLecturas[Codigo],$A7)-_xlfn.MINIFS(tblLecturas[Kilometraje],tblLecturas[Codigo],$A7))/(MAX(1,_xlfn.MAXIFS(tblLecturas[Fecha],tblLecturas[Codigo],$A7)-_xlfn.MINIFS(tblLecturas[Fecha],tblLecturas[Codigo],$A7))),1),ROUND((_xlfn.MAXIFS(tblLecturas[Horometro],tblLecturas[Codigo],$A7)-_xlfn.MINIFS(tblLecturas[Horometro],tblLecturas[Codigo],$A7))/(MAX(1,_xlfn.MAXIFS(tblLecturas[Fecha],tblLecturas[Codigo],$A7)-_xlfn.MINIFS(tblLecturas[Fecha],tblLecturas[Codigo],$A7))),1)),"") -> 0 | L7: =IFERROR(_xlfn.MAXIFS(tblLecturas[Fecha],tblLecturas[Codigo],$A7),"") -> 46105 | M7: =IFERROR(_xlfn.MAXIFS(Lecturas!$C:$C,Lecturas!$B:$B,$A7,Lecturas!$C:$C,">0"),"") -> 0 | N7: =IFERROR(_xlfn.MAXIFS(tblLecturas[Kilometraje],tblLecturas[Codigo],$A7,tblLecturas[Kilometraje],">0"),"") -> 141791 | O7: {=IFERROR(IF($I7="KM",LOOKUP(2,1/(Lecturas!$B:$B=$A7)/(Lecturas!$D:$D>0),Lecturas!$D:$D),LOOKUP(2,1/(Lecturas!$B:$B=$A7)/(Lecturas!$C:$C>0),Lecturas!$C:$C)),"")} | P7: =IFERROR(_xlfn.MAXIFS(tblMantenciones[Fecha],tblMantenciones[Codigo],tblMaestroEquipos[[#This Row],[Codigo]],tblMantenciones[EsPM],"Sí"),"") -> 0 | Q7: =IF(_xlfn.MAXIFS(Mantenciones!$D:$D,Mantenciones!$B:$B,A7)=0,"Sin datos de mantención registrado",_xlfn.MAXIFS(Mantenciones!$D:$D,Mantenciones!$B:$B,A7)) -> Sin datos de mantención registrado | R7: =IFERROR(IF(_xlfn.MAXIFS(Mantenciones!$D:$D,Mantenciones!$B:$B,$A7,Mantenciones!$E:$E,"Sí",Mantenciones!$D:$D,">0")=0,"Sin datos de mantención registrado",_xlfn.MAXIFS(Mantenciones!$D:$D,Mantenciones!$B:$B,$A7,Mantenciones!$E:$E,"Sí",Mantenciones!$D:$D,">0")),"Sin datos de mantención registrado") -> Sin datos de mantención registrado | S7: =IFERROR(SUMIFS(tblMantenciones[Costo Mantencion CLP],tblMantenciones[Codigo],A7),0) -> 0 | T7: =IFERROR(SUMIFS(tblComprasPM[Costo PM CLP],tblComprasPM[Codigo],tblMaestroEquipos[[#This Row],[Codigo]]),0) -> 0 | U7: =IFERROR(tblMaestroEquipos[[#This Row],[Costo Mantenciones CLP]]+tblMaestroEquipos[[#This Row],[Costo Compras PM CLP]],0) -> 0 | V7: =IFERROR(_xlfn.XLOOKUP(tblMaestroEquipos[[#This Row],[Codigo]],tblEquipos[Codigo],tblEquipos[Estado Base]),"") -> Operativo | W7: =IF(OR(TRIM($V7)="Fuera de Servicio",TRIM($V7)="Fuera de servicio"),"FUERA DE SERVICIO",IF(OR(TRIM($V7)="Taller",TRIM($V7)="En taller",TRIM($V7)="EN TALLER"),"EN TALLER",IF($AD7="PENDIENTE","POR RECIBIR",IF(AND($Z7<>"",$AA7=""),"EN PROCESO",IF(AND(ISNUMBER($X7),$X7<0),"ATRASADA",IF(AND(ISNUMBER($X7),$X7<=30),"PRÓXIMA","AL DÍA")))))) -> AL DÍA | X7: =IF(OR(NOT(ISNUMBER(R7)),NOT(ISNUMBER(J7)),NOT(ISNUMBER(O7))),"", (R7+J7)-O7) | Y7: =IFERROR(IF(OR(tblMaestroEquipos[[#This Row],[Estado Operacional]]="FUERA DE SERVICIO",tblMaestroEquipos[[#This Row],[Ultima Fecha Lectura]]="",tblMaestroEquipos[[#This Row],[Dias a Proxima Mantencion]]=""),"",tblMaestroEquipos[[#This Row],[Ultima Fecha Lectura]]+tblMaestroEquipos[[#This Row],[Dias a Proxima Mantencion]]),"") | Z7: =IFERROR(IF(_xlfn.MINIFS(tblComprasPM[Fecha],tblComprasPM[Codigo],tblMaestroEquipos[[#This Row],[Codigo]])=0,"",_xlfn.MINIFS(tblComprasPM[Fecha],tblComprasPM[Codigo],tblMaestroEquipos[[#This Row],[Codigo]])),"") | AA7: =IFERROR(IF(_xlfn.MAXIFS(tblBodega[Fecha],tblBodega[Codigo],tblMaestroEquipos[[#This Row],[Codigo]])=0,"",_xlfn.MAXIFS(tblBodega[Fecha],tblBodega[Codigo],tblMaestroEquipos[[#This Row],[Codigo]])),"") | AB7: =IFERROR(IF(OR(tblMaestroEquipos[[#This Row],[Fecha Compra PM]]="",tblMaestroEquipos[[#This Row],[Fecha Compra PM]]=0),"",IF(OR(tblMaestroEquipos[[#This Row],[Ultima Fecha PM]]="",tblMaestroEquipos[[#This Row],[Ultima Fecha PM]]=0),MAX(0,INT(TODAY())-INT(tblMaestroEquipos[[#This Row],[Fecha Compra PM]])),MAX(0,INT(tblMaestroEquipos[[#This Row],[Ultima Fecha PM]])-INT(tblMaestroEquipos[[#This Row],[Fecha Compra PM]])))),"") | AC7: =IFERROR(IF(OR(tblMaestroEquipos[[#This Row],[Fecha Salida Bodega]]="",tblMaestroEquipos[[#This Row],[Fecha Salida Bodega]]=0),"",IF(OR(tblMaestroEquipos[[#This Row],[Ultima Fecha PM]]="",tblMaestroEquipos[[#This Row],[Ultima Fecha PM]]=0),MAX(0,INT(TODAY())-INT(tblMaestroEquipos[[#This Row],[Fecha Salida Bodega]])),MAX(0,INT(tblMaestroEquipos[[#This Row],[Ultima Fecha PM]])-INT(tblMaestroEquipos[[#This Row],[Fecha Salida Bodega]])))),"") | AD7: =IF(tblMaestroEquipos[[#This Row],[Fecha Salida Bodega]]="","SIN SALIDA BODEGA",IF(OR(tblMaestroEquipos[[#This Row],[Ultima Fecha PM]]="",tblMaestroEquipos[[#This Row],[Ultima Fecha PM]]<tblMaestroEquipos[[#This Row],[Fecha Salida Bodega]]),"PENDIENTE","CERRADO")) -> SIN SALIDA BODEGA | AE7: =IF(TRIM(V7)="Fuera de servicio","FUERA DE SERVICIO", IF(OR(TRIM(V7)="Taller",TRIM(V7)="En taller"),"EN TALLER", IF(W7="ATRASADO","ATRASADO", IF(W7="EN PROCESO","EN PROCESO", IF(W7="PRÓXIMO","PRÓXIMO", "OPERATIVO"))))) -> OPERATIVO | AF7: =IF($AE7="ATRASADA",IF($X7<=-15,"CRÍTICA","ALTA"),IF($AE7="PRÓXIMA","MEDIA",IF(OR($AE7="EN PROCESO",$AE7="POR RECIBIR"),"SEGUIMIENTO",IF($AE7="FUERA DE SERVICIO","NO APLICA","BAJA")))) -> BAJA | AG7: =IF($AE7="FUERA DE SERVICIO","No programar compra",IF($AE7="CERRADO","Cerrar ciclo y preparar siguiente PM",IF($AE7="EN PROCESO","Hacer seguimiento al taller y cerrar report",IF($AE7="POR RECIBIR","Acelerar recepción de repuestos",IF($AE7="ATRASADA","Comprar kit PM y coordinar ejecución",IF($AE7="PRÓXIMA","Planificar compra preventiva","Monitorear próximo vencimiento")))))) -> Monitorear próximo vencimiento | AH7: =IF(AND(OR($AE7="ATRASADA",$AE7="PRÓXIMA"),$Z7="",$AA7=""),1,0) -> 0 | AI7: =IF(OR($AH7=0,$Y7=""),"",SUMPRODUCT(($AH$4:$AH$247=1)*(($Y$4:$Y$247<$Y7)+(($Y$4:$Y$247=$Y7)*(ROW($Y$4:$Y$247)<=ROW()))))) | AJ7: =IF(W7="ATRASADA",1,IF(W7="EN PROCESO",2,IF(W7="POR RECIBIR",3,99))) -> 99
A8: CD-137 | B8: Tracto Camión | C8: Camiones de Ruta | D8: Mercedes Benz | E8: Axor 1936 | F8: 2014 | G8: {=IFERROR(INDEX(Lecturas!$E$4:$E$3549,MATCH(1,(Lecturas!$B$4:$B$3549=$A8)*(Lecturas!$E$4:$E$3549<>"")*(Lecturas!$A$4:$A$3549=_xlfn.MAXIFS(Lecturas!$A$4:$A$3549,Lecturas!$B$4:$B$3549,$A8,Lecturas!$E$4:$E$3549,"<>")),0)),"")} -> Oficina Central | H8: Sin asignar | I8: HORAS | J8: 250 | K8: =IFERROR(IF($I8="KM",ROUND((_xlfn.MAXIFS(tblLecturas[Kilometraje],tblLecturas[Codigo],$A8)-_xlfn.MINIFS(tblLecturas[Kilometraje],tblLecturas[Codigo],$A8))/(MAX(1,_xlfn.MAXIFS(tblLecturas[Fecha],tblLecturas[Codigo],$A8)-_xlfn.MINIFS(tblLecturas[Fecha],tblLecturas[Codigo],$A8))),1),ROUND((_xlfn.MAXIFS(tblLecturas[Horometro],tblLecturas[Codigo],$A8)-_xlfn.MINIFS(tblLecturas[Horometro],tblLecturas[Codigo],$A8))/(MAX(1,_xlfn.MAXIFS(tblLecturas[Fecha],tblLecturas[Codigo],$A8)-_xlfn.MINIFS(tblLecturas[Fecha],tblLecturas[Codigo],$A8))),1)),"") -> 0 | L8: =IFERROR(_xlfn.MAXIFS(tblLecturas[Fecha],tblLecturas[Codigo],$A8),"") -> 46100 | M8: =IFERROR(_xlfn.MAXIFS(Lecturas!$C:$C,Lecturas!$B:$B,$A8,Lecturas!$C:$C,">0"),"") -> 0 | N8: =IFERROR(_xlfn.MAXIFS(tblLecturas[Kilometraje],tblLecturas[Codigo],$A8,tblLecturas[Kilometraje],">0"),"") -> 649418 | O8: {=IFERROR(IF($I8="KM",LOOKUP(2,1/(Lecturas!$B:$B=$A8)/(Lecturas!$D:$D>0),Lecturas!$D:$D),LOOKUP(2,1/(Lecturas!$B:$B=$A8)/(Lecturas!$C:$C>0),Lecturas!$C:$C)),"")} | P8: =IFERROR(_xlfn.MAXIFS(tblMantenciones[Fecha],tblMantenciones[Codigo],tblMaestroEquipos[[#This Row],[Codigo]],tblMantenciones[EsPM],"Sí"),"") -> 0 | Q8: =IF(_xlfn.MAXIFS(Mantenciones!$D:$D,Mantenciones!$B:$B,A8)=0,"Sin datos de mantención registrado",_xlfn.MAXIFS(Mantenciones!$D:$D,Mantenciones!$B:$B,A8)) -> Sin datos de mantención registrado | R8: =IFERROR(IF(_xlfn.MAXIFS(Mantenciones!$D:$D,Mantenciones!$B:$B,$A8,Mantenciones!$E:$E,"Sí",Mantenciones!$D:$D,">0")=0,"Sin datos de mantención registrado",_xlfn.MAXIFS(Mantenciones!$D:$D,Mantenciones!$B:$B,$A8,Mantenciones!$E:$E,"Sí",Mantenciones!$D:$D,">0")),"Sin datos de mantención registrado") -> Sin datos de mantención registrado | S8: =IFERROR(SUMIFS(tblMantenciones[Costo Mantencion CLP],tblMantenciones[Codigo],A8),0) -> 0 | T8: =IFERROR(SUMIFS(tblComprasPM[Costo PM CLP],tblComprasPM[Codigo],tblMaestroEquipos[[#This Row],[Codigo]]),0) -> 223858.04 | U8: =IFERROR(tblMaestroEquipos[[#This Row],[Costo Mantenciones CLP]]+tblMaestroEquipos[[#This Row],[Costo Compras PM CLP]],0) -> 223858.04 | V8: =IFERROR(_xlfn.XLOOKUP(tblMaestroEquipos[[#This Row],[Codigo]],tblEquipos[Codigo],tblEquipos[Estado Base]),"") -> Operativo | W8: =IF(OR(TRIM($V8)="Fuera de Servicio",TRIM($V8)="Fuera de servicio"),"FUERA DE SERVICIO",IF(OR(TRIM($V8)="Taller",TRIM($V8)="En taller",TRIM($V8)="EN TALLER"),"EN TALLER",IF($AD8="PENDIENTE","POR RECIBIR",IF(AND($Z8<>"",$AA8=""),"EN PROCESO",IF(AND(ISNUMBER($X8),$X8<0),"ATRASADA",IF(AND(ISNUMBER($X8),$X8<=30),"PRÓXIMA","AL DÍA")))))) -> EN PROCESO | X8: =IF(OR(NOT(ISNUMBER(R8)),NOT(ISNUMBER(J8)),NOT(ISNUMBER(O8))),"", (R8+J8)-O8) | Y8: =IFERROR(IF(OR(tblMaestroEquipos[[#This Row],[Estado Operacional]]="FUERA DE SERVICIO",tblMaestroEquipos[[#This Row],[Ultima Fecha Lectura]]="",tblMaestroEquipos[[#This Row],[Dias a Proxima Mantencion]]=""),"",tblMaestroEquipos[[#This Row],[Ultima Fecha Lectura]]+tblMaestroEquipos[[#This Row],[Dias a Proxima Mantencion]]),"") | Z8: =IFERROR(IF(_xlfn.MINIFS(tblComprasPM[Fecha],tblComprasPM[Codigo],tblMaestroEquipos[[#This Row],[Codigo]])=0,"",_xlfn.MINIFS(tblComprasPM[Fecha],tblComprasPM[Codigo],tblMaestroEquipos[[#This Row],[Codigo]])),"") -> 46128.535 | AA8: =IFERROR(IF(_xlfn.MAXIFS(tblBodega[Fecha],tblBodega[Codigo],tblMaestroEquipos[[#This Row],[Codigo]])=0,"",_xlfn.MAXIFS(tblBodega[Fecha],tblBodega[Codigo],tblMaestroEquipos[[#This Row],[Codigo]])),"") | AB8: =IFERROR(IF(OR(tblMaestroEquipos[[#This Row],[Fecha Compra PM]]="",tblMaestroEquipos[[#This Row],[Fecha Compra PM]]=0),"",IF(OR(tblMaestroEquipos[[#This Row],[Ultima Fecha PM]]="",tblMaestroEquipos[[#This Row],[Ultima Fecha PM]]=0),MAX(0,INT(TODAY())-INT(tblMaestroEquipos[[#This Row],[Fecha Compra PM]])),MAX(0,INT(tblMaestroEquipos[[#This Row],[Ultima Fecha PM]])-INT(tblMaestroEquipos[[#This Row],[Fecha Compra PM]])))),"") -> 17 | AC8: =IFERROR(IF(OR(tblMaestroEquipos[[#This Row],[Fecha Salida Bodega]]="",tblMaestroEquipos[[#This Row],[Fecha Salida Bodega]]=0),"",IF(OR(tblMaestroEquipos[[#This Row],[Ultima Fecha PM]]="",tblMaestroEquipos[[#This Row],[Ultima Fecha PM]]=0),MAX(0,INT(TODAY())-INT(tblMaestroEquipos[[#This Row],[Fecha Salida Bodega]])),MAX(0,INT(tblMaestroEquipos[[#This Row],[Ultima Fecha PM]])-INT(tblMaestroEquipos[[#This Row],[Fecha Salida Bodega]])))),"") | AD8: =IF(tblMaestroEquipos[[#This Row],[Fecha Salida Bodega]]="","SIN SALIDA BODEGA",IF(OR(tblMaestroEquipos[[#This Row],[Ultima Fecha PM]]="",tblMaestroEquipos[[#This Row],[Ultima Fecha PM]]<tblMaestroEquipos[[#This Row],[Fecha Salida Bodega]]),"PENDIENTE","CERRADO")) -> SIN SALIDA BODEGA | AE8: =IF(TRIM(V8)="Fuera de servicio","FUERA DE SERVICIO", IF(OR(TRIM(V8)="Taller",TRIM(V8)="En taller"),"EN TALLER", IF(W8="ATRASADO","ATRASADO", IF(W8="EN PROCESO","EN PROCESO", IF(W8="PRÓXIMO","PRÓXIMO", "OPERATIVO"))))) -> EN PROCESO | AF8: =IF($AE8="ATRASADA",IF($X8<=-15,"CRÍTICA","ALTA"),IF($AE8="PRÓXIMA","MEDIA",IF(OR($AE8="EN PROCESO",$AE8="POR RECIBIR"),"SEGUIMIENTO",IF($AE8="FUERA DE SERVICIO","NO APLICA","BAJA")))) -> SEGUIMIENTO | AG8: =IF($AE8="FUERA DE SERVICIO","No programar compra",IF($AE8="CERRADO","Cerrar ciclo y preparar siguiente PM",IF($AE8="EN PROCESO","Hacer seguimiento al taller y cerrar report",IF($AE8="POR RECIBIR","Acelerar recepción de repuestos",IF($AE8="ATRASADA","Comprar kit PM y coordinar ejecución",IF($AE8="PRÓXIMA","Planificar compra preventiva","Monitorear próximo vencimiento")))))) -> Hacer seguimiento al taller y cerrar report | AH8: =IF(AND(OR($AE8="ATRASADA",$AE8="PRÓXIMA"),$Z8="",$AA8=""),1,0) -> 0 | AI8: =IF(OR($AH8=0,$Y8=""),"",SUMPRODUCT(($AH$4:$AH$247=1)*(($Y$4:$Y$247<$Y8)+(($Y$4:$Y$247=$Y8)*(ROW($Y$4:$Y$247)<=ROW()))))) | AJ8: =IF(W8="ATRASADA",1,IF(W8="EN PROCESO",2,IF(W8="POR RECIBIR",3,99))) -> 2
